Workbook
Name S_Paper_Production_2019: 'P Data_Inventory'!$D$2

Sheet Content
A1: LAB 1 — ESG Data Quality Assessment Workbook
A2: WORKBOOK CONTENTS
A3: Sheet | B3: Purpose
A4: Data Inventory | B4: Core data entry: 30+ ESG KPIs with quality scoring (your main deliverable)
A5: KPI Checklist | B5: Track which ESG KPIs are available/missing by pillar
A6: Cross-Source Compare | B6: Compare the same 3 KPIs across 3 different sources and compute variance
A7: Summary Dashboard | B7: Auto-calculated summary metrics, heatmap, and quality overview
A8: Rubric | B8: Emission factors, quality scoring rubric, and framework reference
A10: HOW TO START
A11: Step 1 | B11: Start with KPI Checklist — mark which data points you can find for your company
A12: Step 2 | B12: Enter data in Data Inventory. Formulas calculate quality scores automatically.
A13: Step 3 | B13: Complete the Cross-Source Compare sheet for 3 KPIs (one E, one S, one G)
A14: Step 4 | B14: Summary Dashboard — it updates automatically from your data
A15: Step 5 | B15: Write your 150-word data gap analysis in the text box on the Summary sheet
A17: COLOR CODING IN THIS WORKBOOK
A18: Blue text | B18: Hardcoded inputs — cells YOU should fill in
A19: Black text | B19: Formulas — do not edit these
A20: Green text | B20: Cross-sheet references — do not edit these
A21: Yellow background | B21: Cells requiring your attention / inputs
A23: QUALITY SCORE INTERPRETATION
A24: 80 – 100 | B24: HIGH QUALITY — Use with full confidence in analysis
A25: 60 – 79 | B25: ACCEPTABLE — Use with appropriate caveats in report
A26: 40 – 59 | B26: USE WITH CAUTION — Flag as estimated in methodology
A27: 0 – 39 | B27: INSUFFICIENT — Seek alternative source or disclose gap

Sheet 1_Dictionary_Checklist
A1: DATA DICTIONARY -ESG KPI AVAILABILITY- CHECKLIST | G1: CAPSTONE PROJECT
A2: KPI Name | B2: Description | C2: Calculation Logic | D2: Unit | E2: Framework | F2: KPI Source | G2: Availability (✓/P/✗) | H2: Company KPI source | I2: Assurance | J2: Notes
A3: Scope 1 GHG Emissions (tCO₂e) | B3: Direct (Scope 1) greenhouse gas (GHG) emissions. | C3: Activity-level fuel data × emissions factors. Includes natural gas, coal, oil #2, oil #4, oil #6, shale oil, propane, diesel, and biogenic CH4 and N2O; gases included are CO2, CH4 and N2O. | D3: ktonnes CO2e in report; converted to tCO2e in Data Inventory | E3: GRI 305-1; GHG Protocol Corporate Accounting and Reporting Standard | F3: Smurfit Westrock Sustainability Report 2024 | G3: P | H3: 2024 Sustainability Report p.125 and EY schedule p.169: WestRock Scope 1 direct emissions = 5,674 ktonnes CO2e | I3: Limited assurance (EY, legacy WestRock only)
A4: Scope 2 GHG Emissions - Market Based (tCO₂e) | B4: Indirect (Scope 2) market-based greenhouse gas emissions. | C4: Activity-level purchased electricity and steam data × emissions factors under the market-based method; adjusts for renewable energy attributes generated and sold where applicable. | D4: ktonnes CO2e in report; converted to tCO2e in Data Inventory | E4: GRI 305-2; GHG Protocol Scope 2 Guidance | F4: Smurfit Westrock Sustainability Report 2024 | G4: P | H4: 2024 Sustainability Report p.125 and EY schedule p.169: WestRock Scope 2 market-based = 2,300 ktonnes CO2e | I4: Limited assurance (EY, legacy WestRock only)
A5: Scope 2 GHG Emissions - Location Based (tCO₂e) | B5: Indirect (Scope 2) location-based greenhouse gas emissions. | C5: Reported by legacy WestRock in the supporting-data table using the location-based method for purchased energy. The supporting-data table discloses the value directly. | D5: ktonnes CO2e in report; converted to tCO2e in Data Inventory | E5: GRI 305-2; GHG Protocol Scope 2 Guidance | F5: Smurfit Westrock Sustainability Report 2024 | G5: P | H5: 2024 Sustainability Report p.125: WestRock Scope 2 location-based = 1,746 ktonnes CO2e | I5: Self-reported (legacy WestRock table)
A6: Scope 3 GHG Emissions - Total (tCO₂e) | B6: Other indirect (Scope 3) greenhouse gas emissions for relevant categories. | C6: Sum of relevant Scope 3 categories 1, 2, 3, 4, 9, 10 and 12 under the GHG Protocol Corporate Value Chain (Scope 3) Accounting and Reporting Standard. | D6: ktonnes CO2e in report; converted to tCO2e in Data Inventory | E6: GRI 305-3; GHG Protocol Corporate Value Chain (Scope 3) | F6: Smurfit Westrock Sustainability Report 2024 | G6: P | H6: 2024 Sustainability Report p.125 and EY schedule p.171: WestRock Scope 3 relevant categories = 9,452 ktonnes CO2e | I6: Limited assurance (EY, legacy WestRock relevant categories)
A7: Carbon Intensity (tCO₂e per $M revenue) | B7: Template asks for carbon intensity per $M revenue; the report discloses GHG emissions intensity per ton, not per revenue. | C7: Not disclosed on a revenue basis. WestRock reports GHG emissions intensity of 0.55 tCO2e/ton in the supporting-data table. | D7: tCO2e/$M requested by template; report provides tCO2e/ton | E7: GRI 305-4 | F7: Smurfit Westrock Sustainability Report 2024 | G7: ✗ | H7: No directly disclosed carbon intensity per $M revenue in the 2024 Sustainability Report; WestRock instead reports 0.55 tCO2e/ton GHG emissions intensity on p.125 | I7: Not disclosed for revenue basis
A8: Total Energy Consumption (GWh) | B8: Energy consumption within the organization. | C8: Total direct energy consumption + total indirect energy consumption; direct = renewable + non-renewable fuel consumption, indirect = purchased electricity + purchased steam − electricity sold − steam sold. | D8: MMBtu in report; converted to GWh in Data Inventory | E8: GRI 302-1; SASB RR-PP-130a.1 | F8: Smurfit Westrock Sustainability Report 2024 | G8: P | H8: 2024 Sustainability Report p.125 and EY schedule p.175: WestRock total energy used = 284,911,157 MMBtu; converted to GWh for this template | I8: Limited assurance (EY, legacy WestRock energy data)
A9: Renewable Energy Percentage (%) | B9: Share of total energy mix from renewable sources. | C9: Fuel consumption from renewable sources ÷ total energy consumption. | D9: % | E9: GRI 302-1; SASB RR-PP-130a.1 | F9: Smurfit Westrock Sustainability Report 2024 | G9: P | H9: 2024 Sustainability Report p.125 and EY schedule p.175: WestRock energy mix = 60% renewable | I9: Directly disclosed in legacy WestRock energy table
A10: Energy Intensity (GJ per unit of output) | B10: Purchased fuel efficiency / energy intensity for mills. | C10: Purchased energy for mills ÷ tons of paperboard and containerboard produced. Purchased energy includes purchased fuel, electricity, and steam, net of sold electricity where applicable. | D10: MMBtu/ton in report; converted to GJ/ton in Data Inventory | E10: GRI 302-3; DOE Energy Intensity and Baselining Guidance | F10: Smurfit Westrock Sustainability Report 2024 | G10: P | H10: 2024 Sustainability Report p.125 and EY schedule p.175: purchased fuel energy efficiency = 12.62 MMBtu/ton; used as proxy | I10: Proxy from limited-assured WestRock purchased fuel efficiency
A11: Total Water Withdrawal (Megalitres) | B11: Mill water withdrawal from all sources. | C11: Total water intake from surface water, groundwater, and third-party water for mills manufacturing paperboard and containerboard. | D11: Megalitres | E11: GRI 303-3; SASB RR-PP-140a.1 | F11: Smurfit Westrock Sustainability Report 2024 | G11: P | H11: 2024 Sustainability Report p.127 and EY schedule p.175: WestRock mill water withdrawal = 470,201 megalitres | I11: Limited assurance (EY, legacy WestRock mills)
A12: Water Recycled / Reused (%) | B12: Quantitative recycled / reused water percentage. | C12: Not disclosed in the 2024 Sustainability Report. | D12: % | E12: Not disclosed in report | F12: Smurfit Westrock Sustainability Report 2024 | G12: ✗ | H12: No quantitative recycled / reused water percentage disclosed in the 2024 Sustainability Report | I12: Not disclosed
A13: Total Waste Generated (Metric Tonnes) | B13: Mill waste generated across landfill, waste-to-energy, and beneficial-use streams. | C13: Landfill + waste-to-energy + beneficial use. The report gives U.S. short tons; Data Inventory converts to metric tonnes for the template. | D13: U.S. short tons in report; converted to metric tonnes in Data Inventory | E13: GRI 306-3; GRI 306-4; GRI 306-5 | F13: Smurfit Westrock Sustainability Report 2024 | G13: P | H13: 2024 Sustainability Report p.127: WestRock mill waste streams (landfill, waste-to-energy, beneficial use) converted from short tons to metric tonnes | I13: Self-reported / derived (legacy WestRock mills)
A14: Waste Diversion Rate (% not to landfill) | B14: Share of disclosed mill waste not sent to landfill. | C14: (Waste-to-energy + beneficial use) ÷ (landfill + waste-to-energy + beneficial use). Derived from the WestRock mill waste table. | D14: % | E14: GRI 306-4; GRI 306-5 | F14: Smurfit Westrock Sustainability Report 2024 | G14: P | H14: Calculated from 2024 Sustainability Report p.127 WestRock mill waste streams | I14: Calculated from self-reported WestRock mill waste data
... A30: Board Independence (% Independent) | B30: Ratio of non-executive/independent directors | C30: (Independent directors ÷ Total directors) × 100 | D30: % | E30: GRI 2-9 | F30: https://www.globalreporting.org/how-to-use-the-gri-standards/gri-standards-english-language/ | G30: P | H30: 2024 Sustainability Report | I30: Resonable
A31: Women on Board (%) | D31: % | G31: P | H31: 2024 Sustainability Report | I31: Resonable
A32: Average Board Tenure (years) | B32: Average length of service for board members. | C32: Sum of years served ÷ Total directors. | D32: # | E32: IFRS S1 | F32: https://navigator.sasb.ifrs.org/login | G32: X | H32: 2024 Sustainability Report | I32: Resonable
A33: CEO Pay Ratio (CEO to Median Employee) | B33: Pay equity between leadership and staff. | C33: Total CEO compensation ÷ Median employee pay. | D33: % | E33: SEC / ESRS S1 | F33: https://cdn.cdp.net/cdp-production/comfy/cms/files/files/000/006/299/original/CDP's_comment_on_the_European_Sustainability_Reporting_Standards.pdf | G33: X | H33: 2024 Sustainability Report | I33: Resonable
A34: ESG Metrics in Executive Incentive Pay (Y/N) | B34: Whether ESG KPIs affect executive bonuses. | C34: Binary disclosure (Yes/No). | E34: ESRS G1-1 | F34: https://cdn.cdp.net/cdp-production/comfy/cms/files/files/000/006/299/original/CDP's_comment_on_the_European_Sustainability_Reporting_Standards.pdf | G34: X | H34: 2024 Sustainability Report | I34: Resonable
A35: Number of Ethics / Compliance Violations | B35: Total number of confirmed breaches/whistleblows. | C35: Count of substantiated legal or policy breaches. | D35: # | E35: GRI 2-27 | F35: https://www.globalreporting.org/how-to-use-the-gri-standards/gri-standards-english-language/ | G35: X | H35: 2024 Sustainability Report | I35: Resonable
A36: Anti-corruption Policy in Place (Y/N) | B36: Publicly available commitment against bribery. | C36: Binary disclosure (Yes/No). | E36: GRI 205-2 | F36: https://www.globalreporting.org/how-to-use-the-gri-standards/gri-standards-english-language/ | G36: ✓ | H36: 2024 Sustainability Report | I36: Resonable
A37: ESG Assurance Provider | B37: 3rd party validation of information and data | G37: ✓ | H37: 2024 Sustainability Report | I37: Resonable
A39: Annual Revenue ($M) | B39: Net sales for the year. | C39: Direct annual-report figure for 2024 net sales. | D39: USD millions | E39: Annual Report / Form 10-K | F39: Smurfit Westrock 2024 Annual Report | G39: ✓ | H39: 2024 Annual Report pdf p.57 and Segment Information note pdf p.102: net sales (unaffiliated customers) = $21,109 million | I39: Audited annual report
A40: EBITDA Margin (%) | B40: Adjusted EBITDA as a percentage of net sales. | C40: Adjusted EBITDA ÷ net sales × 100. | D40: % | E40: Annual Report non-GAAP reconciliation | F40: Smurfit Westrock 2024 Annual Report | G40: ✓ | H40: Calculated from 2024 Annual Report pdf p.68 Adjusted EBITDA = $3,386 million and pdf p.57 net sales = $21,109 million | I40: Calculated from annual report figures
A41: Capital Expenditure ($M) | B41: Capital expenditures for the year. | C41: Direct annual-report figure for total capital expenditure. | D41: USD millions | E41: Annual Report / Form 10-K | F41: Smurfit Westrock 2024 Annual Report | G41: ✓ | H41: 2024 Annual Report pdf p.105: total capital expenditure = $1,466 million | I41: Audited annual report
A42: Market Capitalization ($M) | B42: Year-end market value of equity. | C42: Year-end closing share price × shares outstanding at December 31, 2024. | D42: USD millions | E42: Calculated from Annual Report + market price | F42: Smurfit Westrock 2024 Annual Report | G42: P | H42: Calculated from 2024 Annual Report pdf p.78 shares outstanding = 520,444,261 and 2024-12-31 closing share price = $51.3218 | I42: Calculated from audited shares and external market price
A43: R&D Expenditure ($M) | B43: Research and development expenditure. | C43: Not separately disclosed in the 2024 Annual Report. | D43: USD millions | E43: Not disclosed in Annual Report | F43: Smurfit Westrock 2024 Annual Report | G43: ✗ | H43: No separate R&D expenditure line disclosed in the 2024 Annual Report | I43: Not disclosed
B45: Count your ✓, P, and ✗ marks and calculate coverage rate below
B46: [Count manually]
B47: [Count manually]
B48: [Count manually]
B49: [=Available / Total KPIs]
B50: [Name the most critical missing KPI and why it matters]

Sheet Sheet1
A1: Pillar (E/S/G/Financial) | B1: E
A3: Sum of (Unit/$ Market Cap) | B3: Column Labels
A4: Row Labels | B4: S | C4: W | D4: Grand Total
A5: Carbon | B5: 1769.052 | C5: 9238.6689 | D5: 11007.721
A6: Scope 1 GHG Emissions | B6: 1478.706 | C6: 3721.0704 | D6: 5199.7764
A7: Scope 2 GHG Emissions (Location-Based) | B7: 290.34599 | C7: 1137.3981 | D7: 1427.7441
A8: Scope 2 GHG Emissions (Market-Based) | C8: 1434.0785 | D8: 1434.0785
A9: Scope 3 GHG Emissions (Total) | C9: 2946.1219 | D9: 2946.1219
A10: Energy | B10: 12.882567 | C10: 106.22946 | D10: 119.11203
A11: Non-Renewable Energy Consumptio | B11: 12.877253 | C11: 19.329786 | D11: 32.207038
A12: Total Energy Consumption | C12: 53.647555 | D12: 53.647555
A13: Total Renewable Energy Consumption | B13: 0.0053138177 | C13: 33.252123 | D13: 33.257437
A14: Sourcing | B14: 3827.7497 | C14: 3135.8245 | D14: 6963.5742
A15: Used Recovered Fiber | B15: 3827.7497 | C15: 3135.8245 | D15: 6963.5742
A16: Waste | B16: 535.73939 | C16: 777.06706 | D16: 1312.8065
A17: Hazardous Waste Generated | B17: 6.6094666 | D17: 6.6094666
A18: Other Waste | B18: 8.84957 | D18: 8.84957
A19: Waste-to-Energy | C19: 167.42728 | D19: 167.42728
A20: Waste-to-Landfill | B20: 256.63346 | C20: 472.5425 | D20: 729.17596
A21: Waste-to-Recovery | B21: 263.6469 | C21: 137.09728 | D21: 400.74418
A22: Grand Total | B22: 6145.4237 | C22: 13257.79 | D22: 19403.214

Sheet ESG
A1: Pillar (E/S/G/Financial) | B1: KPI Category | C1: KPI Name | D1: Total Value | E1: Buisness | F1: Unit | G1: Reporting Year | H1: (Unit/$ Revenue) | I1: (Unit/$ Market Cap)
A2: E | B2: Energy | C2: Total Renewable Energy Consumption | D2: 5 | E2: S | F2: GWh | G2: 2019 | H2: =$D2/IF($E2="S",_xlfn.XLOOKUP($G2,Tables_for_Reference!$J$15:$J$21,Tables_for_Reference!$I$15:$I$21),IF(ESG!$E2="W",_xlfn.XLOOKUP(ESG!$G2,Tables_for_Reference!$J$15:$J$21,Tables_for_Reference!$H$15:$H$21),"Error")) -> 0.00055260831 | I2: =$D2/IF($E2="S",_xlfn.XLOOKUP($G2,Tables_for_Reference!$J$24:$J$29,Tables_for_Reference!$I$24:$I$29),IF(ESG!E2="W",_xlfn.XLOOKUP(ESG!G2,Tables_for_Reference!$J$24:$J$29,Tables_for_Reference!$H$24:$H$29),"Error")) -> 0.00060941423
A3: E | B3: Energy | C3: Total Renewable Energy Consumption | D3: 6 | E3: S | F3: GWh | G3: 2021 | H3: =D3/IF(E3="S",_xlfn.XLOOKUP($G3,Tables_for_Reference!$J$15:$J$21,Tables_for_Reference!$I$15:$I$21),IF(ESG!$E3="W",_xlfn.XLOOKUP(ESG!$G3,Tables_for_Reference!$J$15:$J$21,Tables_for_Reference!$H$15:$H$21),"Error")) -> 0.00059364797 | I3: =$D3/IF($E3="S",_xlfn.XLOOKUP($G3,Tables_for_Reference!$J$24:$J$29,Tables_for_Reference!$I$24:$I$29),IF(ESG!E3="W",_xlfn.XLOOKUP(ESG!G3,Tables_for_Reference!$J$24:$J$29,Tables_for_Reference!$H$24:$H$29),"Error")) -> 0.00048028817
A4: E | B4: Energy | C4: Total Renewable Energy Consumption | D4: 6 | E4: S | F4: GWh | G4: 2020 | H4: =D4/IF(E4="S",_xlfn.XLOOKUP($G4,Tables_for_Reference!$J$15:$J$21,Tables_for_Reference!$I$15:$I$21),IF(ESG!$E4="W",_xlfn.XLOOKUP(ESG!$G4,Tables_for_Reference!$J$15:$J$21,Tables_for_Reference!$H$15:$H$21),"Error")) -> 0.00070339977 | I4: =$D4/IF($E4="S",_xlfn.XLOOKUP($G4,Tables_for_Reference!$J$24:$J$29,Tables_for_Reference!$I$24:$I$29),IF(ESG!E4="W",_xlfn.XLOOKUP(ESG!G4,Tables_for_Reference!$J$24:$J$29,Tables_for_Reference!$H$24:$H$29),"Error")) -> 0.00060617082
A5: E | B5: Energy | C5: Total Renewable Energy Consumption | D5: 8 | E5: S | F5: GWh | G5: 2022 | H5: =D5/IF(E5="S",_xlfn.XLOOKUP($G5,Tables_for_Reference!$J$15:$J$21,Tables_for_Reference!$I$15:$I$21),IF(ESG!$E5="W",_xlfn.XLOOKUP(ESG!$G5,Tables_for_Reference!$J$15:$J$21,Tables_for_Reference!$H$15:$H$21),"Error")) -> 0.00062426844 | I5: =$D5/IF($E5="S",_xlfn.XLOOKUP($G5,Tables_for_Reference!$J$24:$J$29,Tables_for_Reference!$I$24:$I$29),IF(ESG!E5="W",_xlfn.XLOOKUP(ESG!G5,Tables_for_Reference!$J$24:$J$29,Tables_for_Reference!$H$24:$H$29),"Error")) -> 0.00089037284
A6: E | B6: Energy | C6: Total Renewable Energy Consumption | D6: 11 | E6: S | F6: GWh | G6: 2023 | H6: =D6/IF(E6="S",_xlfn.XLOOKUP($G6,Tables_for_Reference!$J$15:$J$21,Tables_for_Reference!$I$15:$I$21),IF(ESG!$E6="W",_xlfn.XLOOKUP(ESG!$G6,Tables_for_Reference!$J$15:$J$21,Tables_for_Reference!$H$15:$H$21),"Error")) -> 0.00097586941 | I6: =$D6/IF($E6="S",_xlfn.XLOOKUP($G6,Tables_for_Reference!$J$24:$J$29,Tables_for_Reference!$I$24:$I$29),IF(ESG!E6="W",_xlfn.XLOOKUP(ESG!G6,Tables_for_Reference!$J$24:$J$29,Tables_for_Reference!$H$24:$H$29),"Error")) -> 0.0011739093
A7: E | B7: Energy | C7: Total Renewable Energy Consumption | D7: 22 | E7: S | F7: GWh | G7: 2024 | H7: =D7/IF(E7="S",_xlfn.XLOOKUP($G7,Tables_for_Reference!$J$15:$J$21,Tables_for_Reference!$I$15:$I$21),IF(ESG!$E7="W",_xlfn.XLOOKUP(ESG!$G7,Tables_for_Reference!$J$15:$J$21,Tables_for_Reference!$H$15:$H$21),"Error")) -> 0.0029200727 | I7: =$D7/IF($E7="S",_xlfn.XLOOKUP($G7,Tables_for_Reference!$J$24:$J$29,Tables_for_Reference!$I$24:$I$29),IF(ESG!E7="W",_xlfn.XLOOKUP(ESG!G7,Tables_for_Reference!$J$24:$J$29,Tables_for_Reference!$H$24:$H$29),"Error")) -> 0.0015536623
A8: E | B8: Carbon | C8: Scope 2 GHG Emissions (Location-Based) | D8: 467 | E8: S | F8: tCO₂e | G8: 2023 | H8: =D8/IF(E8="S",_xlfn.XLOOKUP($G8,Tables_for_Reference!$J$15:$J$21,Tables_for_Reference!$I$15:$I$21),IF(ESG!$E8="W",_xlfn.XLOOKUP(ESG!$G8,Tables_for_Reference!$J$15:$J$21,Tables_for_Reference!$H$15:$H$21),"Error")) -> 0.041430092 | I8: =$D8/IF($E8="S",_xlfn.XLOOKUP($G8,Tables_for_Reference!$J$24:$J$29,Tables_for_Reference!$I$24:$I$29),IF(ESG!E8="W",_xlfn.XLOOKUP(ESG!G8,Tables_for_Reference!$J$24:$J$29,Tables_for_Reference!$H$24:$H$29),"Error")) -> 0.049837787
A9: E | B9: Water | C9: Total BOD Discharged | D9: 8389.5455 | E9: W | F9: Metric Tonnes | G9: 2024 | H9: =D9/IF(E9="S",_xlfn.XLOOKUP($G9,Tables_for_Reference!$J$15:$J$21,Tables_for_Reference!$I$15:$I$21),IF(ESG!$E9="W",_xlfn.XLOOKUP(ESG!$G9,Tables_for_Reference!$J$15:$J$21,Tables_for_Reference!$H$15:$H$21),"Error")) -> 0.61801708 | I9: =$D9/IF($E9="S",_xlfn.XLOOKUP($G9,Tables_for_Reference!$J$24:$J$29,Tables_for_Reference!$I$24:$I$29),IF(ESG!E9="W",_xlfn.XLOOKUP(ESG!G9,Tables_for_Reference!$J$24:$J$29,Tables_for_Reference!$H$24:$H$29),"Error")) -> 0.60482592
A10: E | B10: Waste | C10: Hazardous Waste Generated | D10: 8774 | E10: S | F10: Metric Tonnes | G10: 2021 | H10: =D10/IF(E10="S",_xlfn.XLOOKUP($G10,Tables_for_Reference!$J$15:$J$21,Tables_for_Reference!$I$15:$I$21),IF(ESG!$E10="W",_xlfn.XLOOKUP(ESG!$G10,Tables_for_Reference!$J$15:$J$21,Tables_for_Reference!$H$15:$H$21),"Error")) -> 0.86811121 | I10: =$D10/IF($E10="S",_xlfn.XLOOKUP($G10,Tables_for_Reference!$J$24:$J$29,Tables_for_Reference!$I$24:$I$29),IF(ESG!E10="W",_xlfn.XLOOKUP(ESG!G10,Tables_for_Reference!$J$24:$J$29,Tables_for_Reference!$H$24:$H$29),"Error")) -> 0.7023414
A11: E | B11: Water | C11: Total BOD Discharged | D11: 8875.4545 | E11: W | F11: Metric Tonnes | G11: 2023 | H11: =D11/IF(E11="S",_xlfn.XLOOKUP($G11,Tables_for_Reference!$J$15:$J$21,Tables_for_Reference!$I$15:$I$21),IF(ESG!$E11="W",_xlfn.XLOOKUP(ESG!$G11,Tables_for_Reference!$J$15:$J$21,Tables_for_Reference!$H$15:$H$21),"Error")) -> 0.43699924 | I11: =$D11/IF($E11="S",_xlfn.XLOOKUP($G11,Tables_for_Reference!$J$24:$J$29,Tables_for_Reference!$I$24:$I$29),IF(ESG!E11="W",_xlfn.XLOOKUP(ESG!G11,Tables_for_Reference!$J$24:$J$29,Tables_for_Reference!$H$24:$H$29),"Error")) -> 0.96691991
A12: E | B12: Waste | C12: Other Waste | D12: 9002 | E12: S | F12: Metric Tonnes | G12: 2020 | H12: =D12/IF(E12="S",_xlfn.XLOOKUP($G12,Tables_for_Reference!$J$15:$J$21,Tables_for_Reference!$I$15:$I$21),IF(ESG!$E12="W",_xlfn.XLOOKUP(ESG!$G12,Tables_for_Reference!$J$15:$J$21,Tables_for_Reference!$H$15:$H$21),"Error")) -> 1.0553341 | I12: =$D12/IF($E12="S",_xlfn.XLOOKUP($G12,Tables_for_Reference!$J$24:$J$29,Tables_for_Reference!$I$24:$I$29),IF(ESG!E12="W",_xlfn.XLOOKUP(ESG!G12,Tables_for_Reference!$J$24:$J$29,Tables_for_Reference!$H$24:$H$29),"Error")) -> 0.90945829
A13: E | B13: Water | C13: Total BOD Discharged | D13: 9255 | E13: W | F13: Metric Tonnes | G13: 2020 | H13: =D13/IF(E13="S",_xlfn.XLOOKUP($G13,Tables_for_Reference!$J$15:$J$21,Tables_for_Reference!$I$15:$I$21),IF(ESG!$E13="W",_xlfn.XLOOKUP(ESG!$G13,Tables_for_Reference!$J$15:$J$21,Tables_for_Reference!$H$15:$H$21),"Error")) -> 0.52648645 | I13: =$D13/IF($E13="S",_xlfn.XLOOKUP($G13,Tables_for_Reference!$J$24:$J$29,Tables_for_Reference!$I$24:$I$29),IF(ESG!E13="W",_xlfn.XLOOKUP(ESG!G13,Tables_for_Reference!$J$24:$J$29,Tables_for_Reference!$H$24:$H$29),"Error")) -> 1.0230702
A14: E | B14: Waste | C14: Hazardous Waste Generated | D14: 9655 | E14: S | F14: Metric Tonnes | G14: 2019 | H14: =D14/IF(E14="S",_xlfn.XLOOKUP($G14,Tables_for_Reference!$J$15:$J$21,Tables_for_Reference!$I$15:$I$21),IF(ESG!$E14="W",_xlfn.XLOOKUP(ESG!$G14,Tables_for_Reference!$J$15:$J$21,Tables_for_Reference!$H$15:$H$21),"Error")) -> 1.0670866 | I14: =$D14/IF($E14="S",_xlfn.XLOOKUP($G14,Tables_for_Reference!$J$24:$J$29,Tables_for_Reference!$I$24:$I$29),IF(ESG!E14="W",_xlfn.XLOOKUP(ESG!G14,Tables_for_Reference!$J$24:$J$29,Tables_for_Reference!$H$24:$H$29),"Error")) -> 1.1767789
... A246: S | B246: Diversity | C246: Women in Total Workforce | D246: 9894.888 | E246: S | F246: employees | G246: 2024 | H246: =D246/IF(E246="S",_xlfn.XLOOKUP($G246,Tables_for_Reference!$J$15:$J$21,Tables_for_Reference!$I$15:$I$21),IF(ESG!$E246="W",_xlfn.XLOOKUP(ESG!$G246,Tables_for_Reference!$J$15:$J$21,Tables_for_Reference!$H$15:$H$21),"Error")) -> 1.3133542 | I246: =$D246/IF($E246="S",_xlfn.XLOOKUP($G246,Tables_for_Reference!$J$24:$J$29,Tables_for_Reference!$I$24:$I$29),IF(ESG!E246="W",_xlfn.XLOOKUP(ESG!G246,Tables_for_Reference!$J$24:$J$29,Tables_for_Reference!$H$24:$H$29),"Error")) -> 0.698787
A247: G | B247: Ethics | C247: Anti-corruption Policy in Place (Y/N) | D247: Yes | E247: SW | G247: 2024 | H247: =D247/IF(E247="S",_xlfn.XLOOKUP($G247,Tables_for_Reference!$J$15:$J$21,Tables_for_Reference!$I$15:$I$21),IF(ESG!$E247="W",_xlfn.XLOOKUP(ESG!$G247,Tables_for_Reference!$J$15:$J$21,Tables_for_Reference!$H$15:$H$21),"Error")) -> #VALUE! | I247: =$D247/IF($E247="S",_xlfn.XLOOKUP($G247,Tables_for_Reference!$J$24:$J$29,Tables_for_Reference!$I$24:$I$29),IF(ESG!E247="W",_xlfn.XLOOKUP(ESG!G247,Tables_for_Reference!$J$24:$J$29,Tables_for_Reference!$H$24:$H$29),"Error")) -> #VALUE!
A248: G | B248: Ethics | C248: Anti-corruption Policy in Place (Y/N) | D248: Yes | E248: W | G248: 2023 | H248: =D248/IF(E248="S",_xlfn.XLOOKUP($G248,Tables_for_Reference!$J$15:$J$21,Tables_for_Reference!$I$15:$I$21),IF(ESG!$E248="W",_xlfn.XLOOKUP(ESG!$G248,Tables_for_Reference!$J$15:$J$21,Tables_for_Reference!$H$15:$H$21),"Error")) -> #VALUE! | I248: =$D248/IF($E248="S",_xlfn.XLOOKUP($G248,Tables_for_Reference!$J$24:$J$29,Tables_for_Reference!$I$24:$I$29),IF(ESG!E248="W",_xlfn.XLOOKUP(ESG!G248,Tables_for_Reference!$J$24:$J$29,Tables_for_Reference!$H$24:$H$29),"Error")) -> #VALUE!
A249: G | B249: Ethics | C249: Anti-corruption Policy in Place (Y/N) | D249: Yes | E249: S | G249: 2023 | H249: =D249/IF(E249="S",_xlfn.XLOOKUP($G249,Tables_for_Reference!$J$15:$J$21,Tables_for_Reference!$I$15:$I$21),IF(ESG!$E249="W",_xlfn.XLOOKUP(ESG!$G249,Tables_for_Reference!$J$15:$J$21,Tables_for_Reference!$H$15:$H$21),"Error")) -> #VALUE! | I249: =$D249/IF($E249="S",_xlfn.XLOOKUP($G249,Tables_for_Reference!$J$24:$J$29,Tables_for_Reference!$I$24:$I$29),IF(ESG!E249="W",_xlfn.XLOOKUP(ESG!G249,Tables_for_Reference!$J$24:$J$29,Tables_for_Reference!$H$24:$H$29),"Error")) -> #VALUE!
A250: G | B250: Ethics | C250: Anti-corruption Policy in Place (Y/N) | D250: Yes | E250: W | G250: 2022 | H250: =D250/IF(E250="S",_xlfn.XLOOKUP($G250,Tables_for_Reference!$J$15:$J$21,Tables_for_Reference!$I$15:$I$21),IF(ESG!$E250="W",_xlfn.XLOOKUP(ESG!$G250,Tables_for_Reference!$J$15:$J$21,Tables_for_Reference!$H$15:$H$21),"Error")) -> #VALUE! | I250: =$D250/IF($E250="S",_xlfn.XLOOKUP($G250,Tables_for_Reference!$J$24:$J$29,Tables_for_Reference!$I$24:$I$29),IF(ESG!E250="W",_xlfn.XLOOKUP(ESG!G250,Tables_for_Reference!$J$24:$J$29,Tables_for_Reference!$H$24:$H$29),"Error")) -> #VALUE!
A251: G | B251: Ethics | C251: Anti-corruption Policy in Place (Y/N) | D251: Yes | E251: S | G251: 2022 | H251: =D251/IF(E251="S",_xlfn.XLOOKUP($G251,Tables_for_Reference!$J$15:$J$21,Tables_for_Reference!$I$15:$I$21),IF(ESG!$E251="W",_xlfn.XLOOKUP(ESG!$G251,Tables_for_Reference!$J$15:$J$21,Tables_for_Reference!$H$15:$H$21),"Error")) -> #VALUE! | I251: =$D251/IF($E251="S",_xlfn.XLOOKUP($G251,Tables_for_Reference!$J$24:$J$29,Tables_for_Reference!$I$24:$I$29),IF(ESG!E251="W",_xlfn.XLOOKUP(ESG!G251,Tables_for_Reference!$J$24:$J$29,Tables_for_Reference!$H$24:$H$29),"Error")) -> #VALUE!
A252: G | B252: Ethics | C252: Anti-corruption Policy in Place (Y/N) | D252: Yes | E252: W | G252: 2021 | H252: =D252/IF(E252="S",_xlfn.XLOOKUP($G252,Tables_for_Reference!$J$15:$J$21,Tables_for_Reference!$I$15:$I$21),IF(ESG!$E252="W",_xlfn.XLOOKUP(ESG!$G252,Tables_for_Reference!$J$15:$J$21,Tables_for_Reference!$H$15:$H$21),"Error")) -> #VALUE! | I252: =$D252/IF($E252="S",_xlfn.XLOOKUP($G252,Tables_for_Reference!$J$24:$J$29,Tables_for_Reference!$I$24:$I$29),IF(ESG!E252="W",_xlfn.XLOOKUP(ESG!G252,Tables_for_Reference!$J$24:$J$29,Tables_for_Reference!$H$24:$H$29),"Error")) -> #VALUE!
A253: G | B253: Ethics | C253: Anti-corruption Policy in Place (Y/N) | D253: Yes | E253: S | G253: 2021 | H253: =D253/IF(E253="S",_xlfn.XLOOKUP($G253,Tables_for_Reference!$J$15:$J$21,Tables_for_Reference!$I$15:$I$21),IF(ESG!$E253="W",_xlfn.XLOOKUP(ESG!$G253,Tables_for_Reference!$J$15:$J$21,Tables_for_Reference!$H$15:$H$21),"Error")) -> #VALUE! | I253: =$D253/IF($E253="S",_xlfn.XLOOKUP($G253,Tables_for_Reference!$J$24:$J$29,Tables_for_Reference!$I$24:$I$29),IF(ESG!E253="W",_xlfn.XLOOKUP(ESG!G253,Tables_for_Reference!$J$24:$J$29,Tables_for_Reference!$H$24:$H$29),"Error")) -> #VALUE!
A254: G | B254: Ethics | C254: Anti-corruption Policy in Place (Y/N) | D254: Yes | E254: W | G254: 2020 | H254: =D254/IF(E254="S",_xlfn.XLOOKUP($G254,Tables_for_Reference!$J$15:$J$21,Tables_for_Reference!$I$15:$I$21),IF(ESG!$E254="W",_xlfn.XLOOKUP(ESG!$G254,Tables_for_Reference!$J$15:$J$21,Tables_for_Reference!$H$15:$H$21),"Error")) -> #VALUE! | I254: =$D254/IF($E254="S",_xlfn.XLOOKUP($G254,Tables_for_Reference!$J$24:$J$29,Tables_for_Reference!$I$24:$I$29),IF(ESG!E254="W",_xlfn.XLOOKUP(ESG!G254,Tables_for_Reference!$J$24:$J$29,Tables_for_Reference!$H$24:$H$29),"Error")) -> #VALUE!
A255: G | B255: Ethics | C255: Anti-corruption Policy in Place (Y/N) | D255: Yes | E255: S | G255: 2020 | H255: =D255/IF(E255="S",_xlfn.XLOOKUP($G255,Tables_for_Reference!$J$15:$J$21,Tables_for_Reference!$I$15:$I$21),IF(ESG!$E255="W",_xlfn.XLOOKUP(ESG!$G255,Tables_for_Reference!$J$15:$J$21,Tables_for_Reference!$H$15:$H$21),"Error")) -> #VALUE! | I255: =$D255/IF($E255="S",_xlfn.XLOOKUP($G255,Tables_for_Reference!$J$24:$J$29,Tables_for_Reference!$I$24:$I$29),IF(ESG!E255="W",_xlfn.XLOOKUP(ESG!G255,Tables_for_Reference!$J$24:$J$29,Tables_for_Reference!$H$24:$H$29),"Error")) -> #VALUE!
A256: G | B256: Ethics | C256: Anti-corruption Policy in Place (Y/N) | D256: Yes | E256: W | G256: 2019 | H256: =D256/IF(E256="S",_xlfn.XLOOKUP($G256,Tables_for_Reference!$J$15:$J$21,Tables_for_Reference!$I$15:$I$21),IF(ESG!$E256="W",_xlfn.XLOOKUP(ESG!$G256,Tables_for_Reference!$J$15:$J$21,Tables_for_Reference!$H$15:$H$21),"Error")) -> #VALUE! | I256: =$D256/IF($E256="S",_xlfn.XLOOKUP($G256,Tables_for_Reference!$J$24:$J$29,Tables_for_Reference!$I$24:$I$29),IF(ESG!E256="W",_xlfn.XLOOKUP(ESG!G256,Tables_for_Reference!$J$24:$J$29,Tables_for_Reference!$H$24:$H$29),"Error")) -> #VALUE!
A257: G | B257: Ethics | C257: Anti-corruption Policy in Place (Y/N) | D257: Yes | E257: S | G257: 2019 | H257: =D257/IF(E257="S",_xlfn.XLOOKUP($G257,Tables_for_Reference!$J$15:$J$21,Tables_for_Reference!$I$15:$I$21),IF(ESG!$E257="W",_xlfn.XLOOKUP(ESG!$G257,Tables_for_Reference!$J$15:$J$21,Tables_for_Reference!$H$15:$H$21),"Error")) -> #VALUE! | I257: =$D257/IF($E257="S",_xlfn.XLOOKUP($G257,Tables_for_Reference!$J$24:$J$29,Tables_for_Reference!$I$24:$I$29),IF(ESG!E257="W",_xlfn.XLOOKUP(ESG!G257,Tables_for_Reference!$J$24:$J$29,Tables_for_Reference!$H$24:$H$29),"Error")) -> #VALUE!
A258: G | B258: Board | C258: Total Board Size | D258: 14 | E258: SW | F258: Directors | G258: 2024 | H258: =D258/IF(E258="S",_xlfn.XLOOKUP($G258,Tables_for_Reference!$J$15:$J$21,Tables_for_Reference!$I$15:$I$21),IF(ESG!$E258="W",_xlfn.XLOOKUP(ESG!$G258,Tables_for_Reference!$J$15:$J$21,Tables_for_Reference!$H$15:$H$21),"Error")) -> #VALUE! | I258: =$D258/IF($E258="S",_xlfn.XLOOKUP($G258,Tables_for_Reference!$J$24:$J$29,Tables_for_Reference!$I$24:$I$29),IF(ESG!E258="W",_xlfn.XLOOKUP(ESG!G258,Tables_for_Reference!$J$24:$J$29,Tables_for_Reference!$H$24:$H$29),"Error")) -> #VALUE!
A259: G | B259: Board | C259: Independent Directors | D259: 12 | E259: SW | F259: Directors | G259: 2024 | H259: =D259/IF(E259="S",_xlfn.XLOOKUP($G259,Tables_for_Reference!$J$15:$J$21,Tables_for_Reference!$I$15:$I$21),IF(ESG!$E259="W",_xlfn.XLOOKUP(ESG!$G259,Tables_for_Reference!$J$15:$J$21,Tables_for_Reference!$H$15:$H$21),"Error")) -> #VALUE! | I259: =$D259/IF($E259="S",_xlfn.XLOOKUP($G259,Tables_for_Reference!$J$24:$J$29,Tables_for_Reference!$I$24:$I$29),IF(ESG!E259="W",_xlfn.XLOOKUP(ESG!G259,Tables_for_Reference!$J$24:$J$29,Tables_for_Reference!$H$24:$H$29),"Error")) -> #VALUE!
A260: G | B260: Board | C260: Board Independence (% Independent Directors) | D260: 0.85714286 | E260: SW | F260: % | G260: 2024 | H260: =D260/IF(E260="S",_xlfn.XLOOKUP($G260,Tables_for_Reference!$J$15:$J$21,Tables_for_Reference!$I$15:$I$21),IF(ESG!$E260="W",_xlfn.XLOOKUP(ESG!$G260,Tables_for_Reference!$J$15:$J$21,Tables_for_Reference!$H$15:$H$21),"Error")) -> #VALUE! | I260: =$D260/IF($E260="S",_xlfn.XLOOKUP($G260,Tables_for_Reference!$J$24:$J$29,Tables_for_Reference!$I$24:$I$29),IF(ESG!E260="W",_xlfn.XLOOKUP(ESG!G260,Tables_for_Reference!$J$24:$J$29,Tables_for_Reference!$H$24:$H$29),"Error")) -> #VALUE!
A261: G | B261: Compliance | C261: ESG Assurance Provider | D261: Yes | E261: SW | G261: 2024 | H261: =D261/IF(E261="S",_xlfn.XLOOKUP($G261,Tables_for_Reference!$J$15:$J$21,Tables_for_Reference!$I$15:$I$21),IF(ESG!$E261="W",_xlfn.XLOOKUP(ESG!$G261,Tables_for_Reference!$J$15:$J$21,Tables_for_Reference!$H$15:$H$21),"Error")) -> #VALUE! | I261: =$D261/IF($E261="S",_xlfn.XLOOKUP($G261,Tables_for_Reference!$J$24:$J$29,Tables_for_Reference!$I$24:$I$29),IF(ESG!E261="W",_xlfn.XLOOKUP(ESG!G261,Tables_for_Reference!$J$24:$J$29,Tables_for_Reference!$H$24:$H$29),"Error")) -> #VALUE!
A262: G | B262: Compliance | C262: ESG Assurance Provider | D262: Yes | E262: W | G262: 2023 | H262: =D262/IF(E262="S",_xlfn.XLOOKUP($G262,Tables_for_Reference!$J$15:$J$21,Tables_for_Reference!$I$15:$I$21),IF(ESG!$E262="W",_xlfn.XLOOKUP(ESG!$G262,Tables_for_Reference!$J$15:$J$21,Tables_for_Reference!$H$15:$H$21),"Error")) -> #VALUE! | I262: =$D262/IF($E262="S",_xlfn.XLOOKUP($G262,Tables_for_Reference!$J$24:$J$29,Tables_for_Reference!$I$24:$I$29),IF(ESG!E262="W",_xlfn.XLOOKUP(ESG!G262,Tables_for_Reference!$J$24:$J$29,Tables_for_Reference!$H$24:$H$29),"Error")) -> #VALUE!
A263: G | B263: Compliance | C263: ESG Assurance Provider | D263: Yes | E263: S | G263: 2023 | H263: =D263/IF(E263="S",_xlfn.XLOOKUP($G263,Tables_for_Reference!$J$15:$J$21,Tables_for_Reference!$I$15:$I$21),IF(ESG!$E263="W",_xlfn.XLOOKUP(ESG!$G263,Tables_for_Reference!$J$15:$J$21,Tables_for_Reference!$H$15:$H$21),"Error")) -> #VALUE! | I263: =$D263/IF($E263="S",_xlfn.XLOOKUP($G263,Tables_for_Reference!$J$24:$J$29,Tables_for_Reference!$I$24:$I$29),IF(ESG!E263="W",_xlfn.XLOOKUP(ESG!G263,Tables_for_Reference!$J$24:$J$29,Tables_for_Reference!$H$24:$H$29),"Error")) -> #VALUE!
A264: G | B264: Compliance | C264: ESG Assurance Provider | D264: Yes | E264: W | G264: 2022 | H264: =D264/IF(E264="S",_xlfn.XLOOKUP($G264,Tables_for_Reference!$J$15:$J$21,Tables_for_Reference!$I$15:$I$21),IF(ESG!$E264="W",_xlfn.XLOOKUP(ESG!$G264,Tables_for_Reference!$J$15:$J$21,Tables_for_Reference!$H$15:$H$21),"Error")) -> #VALUE! | I264: =$D264/IF($E264="S",_xlfn.XLOOKUP($G264,Tables_for_Reference!$J$24:$J$29,Tables_for_Reference!$I$24:$I$29),IF(ESG!E264="W",_xlfn.XLOOKUP(ESG!G264,Tables_for_Reference!$J$24:$J$29,Tables_for_Reference!$H$24:$H$29),"Error")) -> #VALUE!
A265: G | B265: Compliance | C265: ESG Assurance Provider | D265: Yes | E265: S | G265: 2022 | H265: =D265/IF(E265="S",_xlfn.XLOOKUP($G265,Tables_for_Reference!$J$15:$J$21,Tables_for_Reference!$I$15:$I$21),IF(ESG!$E265="W",_xlfn.XLOOKUP(ESG!$G265,Tables_for_Reference!$J$15:$J$21,Tables_for_Reference!$H$15:$H$21),"Error")) -> #VALUE! | I265: =$D265/IF($E265="S",_xlfn.XLOOKUP($G265,Tables_for_Reference!$J$24:$J$29,Tables_for_Reference!$I$24:$I$29),IF(ESG!E265="W",_xlfn.XLOOKUP(ESG!G265,Tables_for_Reference!$J$24:$J$29,Tables_for_Reference!$H$24:$H$29),"Error")) -> #VALUE!
A266: G | B266: Compliance | C266: ESG Assurance Provider | D266: Yes | E266: W | G266: 2021 | H266: =D266/IF(E266="S",_xlfn.XLOOKUP($G266,Tables_for_Reference!$J$15:$J$21,Tables_for_Reference!$I$15:$I$21),IF(ESG!$E266="W",_xlfn.XLOOKUP(ESG!$G266,Tables_for_Reference!$J$15:$J$21,Tables_for_Reference!$H$15:$H$21),"Error")) -> #VALUE! | I266: =$D266/IF($E266="S",_xlfn.XLOOKUP($G266,Tables_for_Reference!$J$24:$J$29,Tables_for_Reference!$I$24:$I$29),IF(ESG!E266="W",_xlfn.XLOOKUP(ESG!G266,Tables_for_Reference!$J$24:$J$29,Tables_for_Reference!$H$24:$H$29),"Error")) -> #VALUE!
A267: G | B267: Compliance | C267: ESG Assurance Provider | D267: Yes | E267: S | G267: 2021 | H267: =D267/IF(E267="S",_xlfn.XLOOKUP($G267,Tables_for_Reference!$J$15:$J$21,Tables_for_Reference!$I$15:$I$21),IF(ESG!$E267="W",_xlfn.XLOOKUP(ESG!$G267,Tables_for_Reference!$J$15:$J$21,Tables_for_Reference!$H$15:$H$21),"Error")) -> #VALUE! | I267: =$D267/IF($E267="S",_xlfn.XLOOKUP($G267,Tables_for_Reference!$J$24:$J$29,Tables_for_Reference!$I$24:$I$29),IF(ESG!E267="W",_xlfn.XLOOKUP(ESG!G267,Tables_for_Reference!$J$24:$J$29,Tables_for_Reference!$H$24:$H$29),"Error")) -> #VALUE!
A268: G | B268: Compliance | C268: ESG Assurance Provider | D268: Yes | E268: W | G268: 2020 | H268: =D268/IF(E268="S",_xlfn.XLOOKUP($G268,Tables_for_Reference!$J$15:$J$21,Tables_for_Reference!$I$15:$I$21),IF(ESG!$E268="W",_xlfn.XLOOKUP(ESG!$G268,Tables_for_Reference!$J$15:$J$21,Tables_for_Reference!$H$15:$H$21),"Error")) -> #VALUE! | I268: =$D268/IF($E268="S",_xlfn.XLOOKUP($G268,Tables_for_Reference!$J$24:$J$29,Tables_for_Reference!$I$24:$I$29),IF(ESG!E268="W",_xlfn.XLOOKUP(ESG!G268,Tables_for_Reference!$J$24:$J$29,Tables_for_Reference!$H$24:$H$29),"Error")) -> #VALUE!
A269: G | B269: Compliance | C269: ESG Assurance Provider | D269: Yes | E269: S | G269: 2020 | H269: =D269/IF(E269="S",_xlfn.XLOOKUP($G269,Tables_for_Reference!$J$15:$J$21,Tables_for_Reference!$I$15:$I$21),IF(ESG!$E269="W",_xlfn.XLOOKUP(ESG!$G269,Tables_for_Reference!$J$15:$J$21,Tables_for_Reference!$H$15:$H$21),"Error")) -> #VALUE! | I269: =$D269/IF($E269="S",_xlfn.XLOOKUP($G269,Tables_for_Reference!$J$24:$J$29,Tables_for_Reference!$I$24:$I$29),IF(ESG!E269="W",_xlfn.XLOOKUP(ESG!G269,Tables_for_Reference!$J$24:$J$29,Tables_for_Reference!$H$24:$H$29),"Error")) -> #VALUE!
A270: G | B270: Compliance | C270: ESG Assurance Provider | D270: Yes | E270: W | G270: 2019 | H270: =D270/IF(E270="S",_xlfn.XLOOKUP($G270,Tables_for_Reference!$J$15:$J$21,Tables_for_Reference!$I$15:$I$21),IF(ESG!$E270="W",_xlfn.XLOOKUP(ESG!$G270,Tables_for_Reference!$J$15:$J$21,Tables_for_Reference!$H$15:$H$21),"Error")) -> #VALUE! | I270: =$D270/IF($E270="S",_xlfn.XLOOKUP($G270,Tables_for_Reference!$J$24:$J$29,Tables_for_Reference!$I$24:$I$29),IF(ESG!E270="W",_xlfn.XLOOKUP(ESG!G270,Tables_for_Reference!$J$24:$J$29,Tables_for_Reference!$H$24:$H$29),"Error")) -> #VALUE!
A271: G | B271: Compliance | C271: ESG Assurance Provider | D271: Yes | E271: S | G271: 2019 | H271: =D271/IF(E271="S",_xlfn.XLOOKUP($G271,Tables_for_Reference!$J$15:$J$21,Tables_for_Reference!$I$15:$I$21),IF(ESG!$E271="W",_xlfn.XLOOKUP(ESG!$G271,Tables_for_Reference!$J$15:$J$21,Tables_for_Reference!$H$15:$H$21),"Error")) -> #VALUE! | I271: =$D271/IF($E271="S",_xlfn.XLOOKUP($G271,Tables_for_Reference!$J$24:$J$29,Tables_for_Reference!$I$24:$I$29),IF(ESG!E271="W",_xlfn.XLOOKUP(ESG!G271,Tables_for_Reference!$J$24:$J$29,Tables_for_Reference!$H$24:$H$29),"Error")) -> #VALUE!
...

Sheet E Data_Inventory
A1: ESG DATA INVENTORY & QUALITY SCORING
A2: Company: Smurfit Westrock | D2: Industry: Paper & Packaging | E2: Reporting Year: 2024 | L2: 25=Assured / 15=Self-rep / 5=Est. | M2: 25=Full method / 15=Value only / 0=None | N2: 25=Current yr / 20=1yr old / 5=3+yr | O2: 25=Match / 15=<5% var / 0=No 2nd source | P2: SUM of K+L+M+N | Q2: Auto-calculated
A3: # | B3: Pillar (E/S/G/Financial) | C3: KPI Category | D3: KPI Name | E3: Value (Enter number) | F3: Buisness | G3: Unit | H3: Reporting Year | I3: Source Type | J3: Source URL / Citation | K3: Assurance Level | L3: Accuracy Score (0–25) | M3: Completeness Score (0–25) | N3: Timeliness Score (0–25) | O3: Consistency Score (0–25) | P3: TOTAL Quality Score (0–100) | Q3: Quality Grade | R3: Notes / Caveats
B4: E | C4: Energy | D4: Total Renewable Energy Consumption | E4: 5 | F4: S | G4: GWh | H4: 2019 | I4: Company ESG Report | J4: Smurfit Kappa 2019 Sustainability Report | L4: 25 | M4: 15 | N4: 5 | O4: 15 | P4: =L4+M4+N4+O4 -> 60 | Q4: =IF(P4>=80,"✅ High Quality",IF(P4>=60,"🟡 Acceptable",IF(P4>=40,"⚠️ Use with Caution","🔴 Insufficient"))) -> 🟡 Acceptable
B5: E | C5: Energy | D5: Total Renewable Energy Consumption | E5: 6 | F5: S | G5: GWh | H5: 2021 | I5: Company ESG Report | J5: Smurfit Kappa 2021 Sustainability Report | L5: 25 | M5: 15 | N5: 5 | O5: 15 | P5: =L5+M5+N5+O5 -> 60 | Q5: =IF(P5>=80,"✅ High Quality",IF(P5>=60,"🟡 Acceptable",IF(P5>=40,"⚠️ Use with Caution","🔴 Insufficient"))) -> 🟡 Acceptable
B6: E | C6: Energy | D6: Total Renewable Energy Consumption | E6: 6 | F6: S | G6: GWh | H6: 2020 | I6: Company ESG Report | J6: Smurfit Kappa 2021 Sustainability Report | L6: 25 | M6: 15 | N6: 5 | O6: 15 | P6: =L6+M6+N6+O6 -> 60 | Q6: =IF(P6>=80,"✅ High Quality",IF(P6>=60,"🟡 Acceptable",IF(P6>=40,"⚠️ Use with Caution","🔴 Insufficient"))) -> 🟡 Acceptable
B7: E | C7: Energy | D7: Total Renewable Energy Consumption | E7: 8 | F7: S | G7: GWh | H7: 2022 | I7: Company ESG Report | J7: Smurfit Kappa 2022 Sustainability Report | L7: 25 | M7: 15 | N7: 20 | O7: 15 | P7: =L7+M7+N7+O7 -> 75 | Q7: =IF(P7>=80,"✅ High Quality",IF(P7>=60,"🟡 Acceptable",IF(P7>=40,"⚠️ Use with Caution","🔴 Insufficient"))) -> 🟡 Acceptable
B8: E | C8: Energy | D8: Total Renewable Energy Consumption | E8: 11 | F8: S | G8: GWh | H8: 2023 | I8: Company ESG Report | J8: Smurfit Kappa 2023 Sustainability Report | L8: 25 | M8: 15 | N8: 25 | O8: 15 | P8: =L8+M8+N8+O8 -> 80 | Q8: =IF(P8>=80,"✅ High Quality",IF(P8>=60,"🟡 Acceptable",IF(P8>=40,"⚠️ Use with Caution","🔴 Insufficient"))) -> ✅ High Quality
B9: E | C9: Energy | D9: Total Renewable Energy Consumption | E9: 22 | F9: S | G9: GWh | H9: 2024 | I9: Company ESG Report | J9: Smurfit Westrock 2024 Sustainability Report | L9: 25 | M9: 15 | N9: 25 | O9: 15 | P9: =L9+M9+N9+O9 -> 80 | Q9: =IF(P9>=80,"✅ High Quality",IF(P9>=60,"🟡 Acceptable",IF(P9>=40,"⚠️ Use with Caution","🔴 Insufficient"))) -> ✅ High Quality
B10: E | C10: Carbon | D10: Scope 2 GHG Emissions (Location-Based) | E10: 467 | F10: S | G10: tCO₂e | H10: 2023 | I10: Company ESG Report | J10: Smurfit Kappa 2023 Sustainability Report | L10: 25 | M10: 15 | N10: 25 | O10: 15 | P10: =L10+M10+N10+O10 -> 80 | Q10: =IF(P10>=80,"✅ High Quality",IF(P10>=60,"🟡 Acceptable",IF(P10>=40,"⚠️ Use with Caution","🔴 Insufficient"))) -> ✅ High Quality
B11: E | C11: Water | D11: Total BOD Discharged | E11: 8389.5455 | F11: W | G11: Metric Tonnes | H11: 2024 | I11: Company ESG Report | J11: Smurfit Westrock 2024 Sustainability Report | L11: 25 | M11: 15 | N11: 25 | O11: 15 | P11: =L11+M11+N11+O11 -> 80 | Q11: =IF(P11>=80,"✅ High Quality",IF(P11>=60,"🟡 Acceptable",IF(P11>=40,"⚠️ Use with Caution","🔴 Insufficient"))) -> ✅ High Quality
B12: E | C12: Waste | D12: Hazardous Waste Generated | E12: 8774 | F12: S | G12: Metric Tonnes | H12: 2021 | I12: Company ESG Report | J12: Smurfit Kappa 2021 Sustainability Report | L12: 25 | M12: 15 | N12: 5 | O12: 15 | P12: =L12+M12+N12+O12 -> 60 | Q12: =IF(P12>=80,"✅ High Quality",IF(P12>=60,"🟡 Acceptable",IF(P12>=40,"⚠️ Use with Caution","🔴 Insufficient"))) -> 🟡 Acceptable
B13: E | C13: Water | D13: Total BOD Discharged | E13: 8875.4545 | F13: W | G13: Metric Tonnes | H13: 2023 | I13: Company ESG Report | J13: Westrock 2023 Sustainability Report | L13: 25 | M13: 15 | N13: 25 | O13: 15 | P13: =L13+M13+N13+O13 -> 80 | Q13: =IF(P13>=80,"✅ High Quality",IF(P13>=60,"🟡 Acceptable",IF(P13>=40,"⚠️ Use with Caution","🔴 Insufficient"))) -> ✅ High Quality
B14: E | C14: Waste | D14: Other Waste | E14: 9002 | F14: S | G14: Metric Tonnes | H14: 2020 | I14: Company ESG Report | J14: Smurfit Kappa 2021 Sustainability Report | L14: 25 | M14: 15 | N14: 5 | O14: 15 | P14: =L14+M14+N14+O14 -> 60 | Q14: =IF(P14>=80,"✅ High Quality",IF(P14>=60,"🟡 Acceptable",IF(P14>=40,"⚠️ Use with Caution","🔴 Insufficient"))) -> 🟡 Acceptable
B15: E | C15: Water | D15: Total BOD Discharged | E15: 9255 | F15: W | G15: Metric Tonnes | H15: 2020 | I15: Company ESG Report | J15: Westrock 2020 GRI Report | L15: 25 | M15: 15 | N15: 5 | O15: 15 | P15: =L15+M15+N15+O15 -> 60 | Q15: =IF(P15>=80,"✅ High Quality",IF(P15>=60,"🟡 Acceptable",IF(P15>=40,"⚠️ Use with Caution","🔴 Insufficient"))) -> 🟡 Acceptable
... B178: E | C178: Water | D178: Total Water Withdrawal | E178: 588952000 | F178: W | G178: m3 | H178: 2020 | I178: Company ESG Report | J178: Westrock 2020 GRI Report | L178: 25 | M178: 15 | N178: 5 | O178: 15 | P178: =L178+M178+N178+O178 -> 60 | Q178: =IF(P178>=80,"✅ High Quality",IF(P178>=60,"🟡 Acceptable",IF(P178>=40,"⚠️ Use with Caution","🔴 Insufficient"))) -> 🟡 Acceptable
B179: E | C179: Water | D179: Water Recycled / Reused (%) | F179: W | G179: % | H179: 2024 | I179: Calculated | L179: 0 | M179: 0 | N179: 0 | O179: 15 | P179: =L179+M179+N179+O179 -> 15 | Q179: =IF(P179>=80,"✅ High Quality",IF(P179>=60,"🟡 Acceptable",IF(P179>=40,"⚠️ Use with Caution","🔴 Insufficient"))) -> 🔴 Insufficient
B180: E | C180: Water | D180: Water Recycled / Reused (%) | F180: S | G180: % | H180: 2024 | I180: Calculated | L180: 0 | M180: 0 | N180: 0 | O180: 15 | P180: =L180+M180+N180+O180 -> 15 | Q180: =IF(P180>=80,"✅ High Quality",IF(P180>=60,"🟡 Acceptable",IF(P180>=40,"⚠️ Use with Caution","🔴 Insufficient"))) -> 🔴 Insufficient
B181: E | C181: Water | D181: Water Recycled / Reused (%) | F181: W | G181: % | H181: 2023 | I181: Calculated | L181: 0 | M181: 0 | N181: 0 | O181: 15 | P181: =L181+M181+N181+O181 -> 15 | Q181: =IF(P181>=80,"✅ High Quality",IF(P181>=60,"🟡 Acceptable",IF(P181>=40,"⚠️ Use with Caution","🔴 Insufficient"))) -> 🔴 Insufficient
B182: E | C182: Water | D182: Water Recycled / Reused (%) | F182: S | G182: % | H182: 2023 | I182: Calculated | L182: 0 | M182: 0 | N182: 0 | O182: 15 | P182: =L182+M182+N182+O182 -> 15 | Q182: =IF(P182>=80,"✅ High Quality",IF(P182>=60,"🟡 Acceptable",IF(P182>=40,"⚠️ Use with Caution","🔴 Insufficient"))) -> 🔴 Insufficient
B183: E | C183: Water | D183: Water Recycled / Reused (%) | F183: W | G183: % | H183: 2022 | I183: Calculated | L183: 0 | M183: 0 | N183: 0 | O183: 15 | P183: =L183+M183+N183+O183 -> 15 | Q183: =IF(P183>=80,"✅ High Quality",IF(P183>=60,"🟡 Acceptable",IF(P183>=40,"⚠️ Use with Caution","🔴 Insufficient"))) -> 🔴 Insufficient
B184: E | C184: Water | D184: Water Recycled / Reused (%) | F184: S | G184: % | H184: 2022 | I184: Calculated | L184: 0 | M184: 0 | N184: 0 | O184: 15 | P184: =L184+M184+N184+O184 -> 15 | Q184: =IF(P184>=80,"✅ High Quality",IF(P184>=60,"🟡 Acceptable",IF(P184>=40,"⚠️ Use with Caution","🔴 Insufficient"))) -> 🔴 Insufficient
B185: E | C185: Water | D185: Water Recycled / Reused (%) | F185: W | G185: % | H185: 2021 | I185: Calculated | L185: 0 | M185: 0 | N185: 0 | O185: 15 | P185: =L185+M185+N185+O185 -> 15 | Q185: =IF(P185>=80,"✅ High Quality",IF(P185>=60,"🟡 Acceptable",IF(P185>=40,"⚠️ Use with Caution","🔴 Insufficient"))) -> 🔴 Insufficient
B186: E | C186: Water | D186: Water Recycled / Reused (%) | F186: S | G186: % | H186: 2021 | I186: Calculated | L186: 0 | M186: 0 | N186: 0 | O186: 15 | P186: =L186+M186+N186+O186 -> 15 | Q186: =IF(P186>=80,"✅ High Quality",IF(P186>=60,"🟡 Acceptable",IF(P186>=40,"⚠️ Use with Caution","🔴 Insufficient"))) -> 🔴 Insufficient
B187: E | C187: Water | D187: Water Recycled / Reused (%) | F187: W | G187: % | H187: 2020 | I187: Calculated | L187: 0 | M187: 0 | N187: 0 | O187: 15 | P187: =L187+M187+N187+O187 -> 15 | Q187: =IF(P187>=80,"✅ High Quality",IF(P187>=60,"🟡 Acceptable",IF(P187>=40,"⚠️ Use with Caution","🔴 Insufficient"))) -> 🔴 Insufficient
B188: E | C188: Water | D188: Water Recycled / Reused (%) | F188: S | G188: % | H188: 2020 | I188: Calculated | L188: 0 | M188: 0 | N188: 0 | O188: 15 | P188: =L188+M188+N188+O188 -> 15 | Q188: =IF(P188>=80,"✅ High Quality",IF(P188>=60,"🟡 Acceptable",IF(P188>=40,"⚠️ Use with Caution","🔴 Insufficient"))) -> 🔴 Insufficient
B189: E | C189: Water | D189: Water Recycled / Reused (%) | F189: W | G189: % | H189: 2019 | I189: Calculated | L189: 0 | M189: 0 | N189: 0 | O189: 15 | P189: =L189+M189+N189+O189 -> 15 | Q189: =IF(P189>=80,"✅ High Quality",IF(P189>=60,"🟡 Acceptable",IF(P189>=40,"⚠️ Use with Caution","🔴 Insufficient"))) -> 🔴 Insufficient
B190: E | C190: Water | D190: Water Recycled / Reused (%) | F190: S | G190: % | H190: 2019 | I190: Calculated | L190: 0 | M190: 0 | N190: 0 | O190: 15 | P190: =L190+M190+N190+O190 -> 15 | Q190: =IF(P190>=80,"✅ High Quality",IF(P190>=60,"🟡 Acceptable",IF(P190>=40,"⚠️ Use with Caution","🔴 Insufficient"))) -> 🔴 Insufficient
... B224: E | C224: Energy | D224: Total Energy Consumption | F224: S | G224: GWh | H224: 2019 | I224: Calculated | L224: 25 | M224: 15 | N224: 0 | O224: 15 | P224: =L224+M224+N224+O224 -> 55 | Q224: =IF(P224>=80,"✅ High Quality",IF(P224>=60,"🟡 Acceptable",IF(P224>=40,"⚠️ Use with Caution","🔴 Insufficient"))) -> ⚠️ Use with Caution
B225: E | C225: Carbon | D225: Scope 2 GHG Emissions (Market-Based) | F225: S | G225: tCO₂e | H225: 2024 | L225: 25 | M225: 10 | N225: 0 | O225: 15 | P225: =L225+M225+N225+O225 -> 50 | Q225: =IF(P225>=80,"✅ High Quality",IF(P225>=60,"🟡 Acceptable",IF(P225>=40,"⚠️ Use with Caution","🔴 Insufficient"))) -> ⚠️ Use with Caution
B226: E | C226: Carbon | D226: Scope 2 GHG Emissions (Market-Based) | F226: S | G226: tCO₂e | H226: 2023 | L226: 25 | M226: 10 | N226: 0 | O226: 15 | P226: =L226+M226+N226+O226 -> 50 | Q226: =IF(P226>=80,"✅ High Quality",IF(P226>=60,"🟡 Acceptable",IF(P226>=40,"⚠️ Use with Caution","🔴 Insufficient"))) -> ⚠️ Use with Caution
B227: E | C227: Carbon | D227: Scope 2 GHG Emissions (Market-Based) | F227: S | G227: tCO₂e | H227: 2022 | L227: 25 | M227: 10 | N227: 0 | O227: 15 | P227: =L227+M227+N227+O227 -> 50 | Q227: =IF(P227>=80,"✅ High Quality",IF(P227>=60,"🟡 Acceptable",IF(P227>=40,"⚠️ Use with Caution","🔴 Insufficient"))) -> ⚠️ Use with Caution
B228: E | C228: Carbon | D228: Scope 2 GHG Emissions (Market-Based) | F228: S | G228: tCO₂e | H228: 2021 | L228: 25 | M228: 10 | N228: 0 | O228: 15 | P228: =L228+M228+N228+O228 -> 50 | Q228: =IF(P228>=80,"✅ High Quality",IF(P228>=60,"🟡 Acceptable",IF(P228>=40,"⚠️ Use with Caution","🔴 Insufficient"))) -> ⚠️ Use with Caution
B229: E | C229: Carbon | D229: Scope 2 GHG Emissions (Market-Based) | F229: S | G229: tCO₂e | H229: 2020 | L229: 25 | M229: 10 | N229: 0 | O229: 15 | P229: =L229+M229+N229+O229 -> 50 | Q229: =IF(P229>=80,"✅ High Quality",IF(P229>=60,"🟡 Acceptable",IF(P229>=40,"⚠️ Use with Caution","🔴 Insufficient"))) -> ⚠️ Use with Caution
B230: E | C230: Carbon | D230: Scope 2 GHG Emissions (Market-Based) | F230: S | G230: tCO₂e | H230: 2019 | L230: 25 | M230: 10 | N230: 0 | O230: 15 | P230: =L230+M230+N230+O230 -> 50 | Q230: =IF(P230>=80,"✅ High Quality",IF(P230>=60,"🟡 Acceptable",IF(P230>=40,"⚠️ Use with Caution","🔴 Insufficient"))) -> ⚠️ Use with Caution
B231: E | C231: Carbon | D231: Scope 3 GHG Emissions (Total) | F231: W | G231: tCO₂e | H231: 2024 | L231: 25 | M231: 10 | N231: 0 | O231: 15 | P231: =L231+M231+N231+O231 -> 50 | Q231: =IF(P231>=80,"✅ High Quality",IF(P231>=60,"🟡 Acceptable",IF(P231>=40,"⚠️ Use with Caution","🔴 Insufficient"))) -> ⚠️ Use with Caution
B232: E | C232: Carbon | D232: Scope 3 GHG Emissions (Total) | F232: S | G232: tCO₂e | H232: 2024 | L232: 25 | M232: 10 | N232: 0 | O232: 15 | P232: =L232+M232+N232+O232 -> 50 | Q232: =IF(P232>=80,"✅ High Quality",IF(P232>=60,"🟡 Acceptable",IF(P232>=40,"⚠️ Use with Caution","🔴 Insufficient"))) -> ⚠️ Use with Caution
B233: E | C233: Carbon | D233: Scope 3 GHG Emissions (Total) | F233: S | G233: tCO₂e | H233: 2023 | L233: 25 | M233: 10 | N233: 0 | O233: 15 | P233: =L233+M233+N233+O233 -> 50 | Q233: =IF(P233>=80,"✅ High Quality",IF(P233>=60,"🟡 Acceptable",IF(P233>=40,"⚠️ Use with Caution","🔴 Insufficient"))) -> ⚠️ Use with Caution
B234: E | C234: Carbon | D234: Scope 3 GHG Emissions (Total) | F234: W | G234: tCO₂e | H234: 2022 | L234: 25 | M234: 10 | N234: 0 | O234: 15 | P234: =L234+M234+N234+O234 -> 50 | Q234: =IF(P234>=80,"✅ High Quality",IF(P234>=60,"🟡 Acceptable",IF(P234>=40,"⚠️ Use with Caution","🔴 Insufficient"))) -> ⚠️ Use with Caution
B235: E | C235: Carbon | D235: Scope 3 GHG Emissions (Total) | F235: S | G235: tCO₂e | H235: 2022 | L235: 25 | M235: 10 | N235: 0 | O235: 15 | P235: =L235+M235+N235+O235 -> 50 | Q235: =IF(P235>=80,"✅ High Quality",IF(P235>=60,"🟡 Acceptable",IF(P235>=40,"⚠️ Use with Caution","🔴 Insufficient"))) -> ⚠️ Use with Caution
...

Sheet S Data_Inventory 
A1: ESG DATA INVENTORY & QUALITY SCORING
A2: Company: Smurfit Westrock | D2: Industry: Paper & Packaging | E2: Reporting Year: 2024 | L2: 25=Assured / 15=Self-rep / 5=Est. | M2: 25=Full method / 15=Value only / 0=None | N2: 25=Current yr / 20=1yr old / 5=3+yr | O2: 25=Match / 15=<5% var / 0=No 2nd source | P2: SUM of K+L+M+N | Q2: Auto-calculated
A3: # | B3: Pillar (E/S/G/Financial) | C3: KPI Category | D3: KPI Name | E3: Value (Enter number) | F3: Buisness | G3: Unit | H3: Reporting Year | I3: Source Type | J3: Source URL / Citation | K3: Assurance Level | L3: Accuracy Score (0–25) | M3: Completeness Score (0–25) | N3: Timeliness Score (0–25) | O3: Consistency Score (0–25) | P3: TOTAL Quality Score (0–100) | Q3: Quality Grade | R3: Notes / Caveats
B4: S | C4: Training | D4: Average Training Hours per Employee | E4: 14 | F4: W | G4: Hours/employee | H4: 2024 | I4: Company ESG Report | J4: Smurfit Westrock 2024 Sustainability Report | L4: 25 | M4: 15 | N4: =_xlfn.XLOOKUP(H4,'E Data_Inventory'!$H$3:$H$240,'E Data_Inventory'!N$3:N$240) -> 25 | O4: 20 | P4: =L4+M4+N4+O4 -> 85 | Q4: =IF(P4>=80,"✅ High Quality",IF(P4>=60,"🟡 Acceptable",IF(P4>=40,"⚠️ Use with Caution","🔴 Insufficient"))) -> ✅ High Quality
B5: S | C5: Training | D5: Average Training Hours per Employee | E5: 22 | F5: S | G5: Hours/employee | H5: 2019 | I5: Company ESG Report | J5: Smurfit Kappa 2021 Sustainability Report | L5: 25 | M5: 15 | N5: =_xlfn.XLOOKUP(H5,'E Data_Inventory'!$H$3:$H$240,'E Data_Inventory'!N$3:N$240) -> 5 | O5: 20 | P5: =L5+M5+N5+O5 -> 65 | Q5: =IF(P5>=80,"✅ High Quality",IF(P5>=60,"🟡 Acceptable",IF(P5>=40,"⚠️ Use with Caution","🔴 Insufficient"))) -> 🟡 Acceptable
B6: S | C6: Training | D6: Average Training Hours per Employee | E6: 11 | F6: W | G6: Hours/employee | H6: 2023 | I6: Company ESG Report | J6: Smurfit Kappa 2023 Sustainability Report | L6: 25 | M6: 15 | N6: =_xlfn.XLOOKUP(H6,'E Data_Inventory'!$H$3:$H$240,'E Data_Inventory'!N$3:N$240) -> 25 | O6: 20 | P6: =L6+M6+N6+O6 -> 85 | Q6: =IF(P6>=80,"✅ High Quality",IF(P6>=60,"🟡 Acceptable",IF(P6>=40,"⚠️ Use with Caution","🔴 Insufficient"))) -> ✅ High Quality
B7: S | C7: Workforce | D7: Total Number of Employees | E7: 46237 | F7: S | G7: Headcount | H7: 2019 | I7: Company ESG Report | J7: Smurfit Kappa 2022 Sustainability Report | L7: 25 | M7: 15 | N7: =_xlfn.XLOOKUP(H7,'E Data_Inventory'!$H$3:$H$240,'E Data_Inventory'!N$3:N$240) -> 5 | O7: 20 | P7: =L7+M7+N7+O7 -> 65 | Q7: =IF(P7>=80,"✅ High Quality",IF(P7>=60,"🟡 Acceptable",IF(P7>=40,"⚠️ Use with Caution","🔴 Insufficient"))) -> 🟡 Acceptable
B8: S | C8: Training | D8: Average Training Hours per Employee | E8: 8 | F8: W | G8: Hours/employee | H8: 2022 | I8: Company ESG Report | J8: Smurfit Westrock 2024 Sustainability Report | L8: 25 | M8: 15 | N8: =_xlfn.XLOOKUP(H8,'E Data_Inventory'!$H$3:$H$240,'E Data_Inventory'!N$3:N$240) -> 20 | O8: 20 | P8: =L8+M8+N8+O8 -> 80 | Q8: =IF(P8>=80,"✅ High Quality",IF(P8>=60,"🟡 Acceptable",IF(P8>=40,"⚠️ Use with Caution","🔴 Insufficient"))) -> ✅ High Quality
B9: S | C9: Safety | D9: Total Recordable Incident Rate (TRIR) | E9: 0.84 | F9: S | G9: Rate per 200k hrs | H9: 2019 | I9: Company ESG Report | J9: Smurfit Westrock 2024 Sustainability Report | L9: 25 | M9: 15 | N9: =_xlfn.XLOOKUP(H9,'E Data_Inventory'!$H$3:$H$240,'E Data_Inventory'!N$3:N$240) -> 5 | O9: 20 | P9: =L9+M9+N9+O9 -> 65 | Q9: =IF(P9>=80,"✅ High Quality",IF(P9>=60,"🟡 Acceptable",IF(P9>=40,"⚠️ Use with Caution","🔴 Insufficient"))) -> 🟡 Acceptable
B10: S | C10: Training | D10: Average Training Hours per Employee | E10: 11 | F10: W | G10: Hours/employee | H10: 2021 | I10: Company ESG Report | J10: Smurfit Westrock 2024 Sustainability Report | L10: 25 | M10: 15 | N10: =_xlfn.XLOOKUP(H10,'E Data_Inventory'!$H$3:$H$240,'E Data_Inventory'!N$3:N$240) -> 5 | O10: 20 | P10: =L10+M10+N10+O10 -> 65 | Q10: =IF(P10>=80,"✅ High Quality",IF(P10>=60,"🟡 Acceptable",IF(P10>=40,"⚠️ Use with Caution","🔴 Insufficient"))) -> 🟡 Acceptable
B11: S | C11: Training | D11: Total Training Hours | E11: =$E$13*$E$31 -> 843.57 | F11: S | G11: Hours | H11: 2019 | I11: Company ESG Report | J11: Smurfit Westrock 2024 Sustainability Report | L11: 25 | M11: 15 | N11: =_xlfn.XLOOKUP(H11,'E Data_Inventory'!$H$3:$H$240,'E Data_Inventory'!N$3:N$240) -> 5 | O11: 20 | P11: =L11+M11+N11+O11 -> 65 | Q11: =IF(P11>=80,"✅ High Quality",IF(P11>=60,"🟡 Acceptable",IF(P11>=40,"⚠️ Use with Caution","🔴 Insufficient"))) -> 🟡 Acceptable
B12: S | C12: Workforce | D12: Turnover | E12: 4842 | F12: S | G12: employees | H12: 2019 | I12: Company ESG Report | J12: Smurfit Kappa 2021 Sustainability Report | L12: 25 | M12: 15 | N12: =_xlfn.XLOOKUP(H12,'E Data_Inventory'!$H$3:$H$240,'E Data_Inventory'!N$3:N$240) -> 5 | O12: 20 | P12: =L12+M12+N12+O12 -> 65 | Q12: =IF(P12>=80,"✅ High Quality",IF(P12>=60,"🟡 Acceptable",IF(P12>=40,"⚠️ Use with Caution","🔴 Insufficient"))) -> 🟡 Acceptable
B13: S | C13: Diversity | D13: Women in Senior Management | E13: 0.21 | F13: S | G13: % | H13: 2019 | I13: Company ESG Report | J13: Westrock 2023 Sustainability Report | L13: 25 | M13: 15 | N13: =_xlfn.XLOOKUP(H13,'E Data_Inventory'!$H$3:$H$240,'E Data_Inventory'!N$3:N$240) -> 5 | O13: 20 | P13: =L13+M13+N13+O13 -> 65 | Q13: =IF(P13>=80,"✅ High Quality",IF(P13>=60,"🟡 Acceptable",IF(P13>=40,"⚠️ Use with Caution","🔴 Insufficient"))) -> 🟡 Acceptable
B14: S | C14: Safety | D14: Total Recordable Incident Rate (TRIR) | E14: 1.34 | F14: W | G14: Rate per 200k hrs | H14: 2024 | I14: Company ESG Report | J14: Smurfit Kappa 2021 Sustainability Report | L14: 25 | M14: 15 | N14: =_xlfn.XLOOKUP(H14,'E Data_Inventory'!$H$3:$H$240,'E Data_Inventory'!N$3:N$240) -> 25 | O14: 20 | P14: =L14+M14+N14+O14 -> 85 | Q14: =IF(P14>=80,"✅ High Quality",IF(P14>=60,"🟡 Acceptable",IF(P14>=40,"⚠️ Use with Caution","🔴 Insufficient"))) -> ✅ High Quality
B15: S | C15: Safety | D15: Total Recordable Incident Rate (TRIR) | E15: 1.52 | F15: W | G15: Rate per 200k hrs | H15: 2023 | I15: Company ESG Report | J15: Smurfit Kappa 2021 Sustainability Report | L15: 25 | M15: 15 | N15: =_xlfn.XLOOKUP(H15,'E Data_Inventory'!$H$3:$H$240,'E Data_Inventory'!N$3:N$240) -> 25 | O15: 20 | P15: =L15+M15+N15+O15 -> 85 | Q15: =IF(P15>=80,"✅ High Quality",IF(P15>=60,"🟡 Acceptable",IF(P15>=40,"⚠️ Use with Caution","🔴 Insufficient"))) -> ✅ High Quality
B16: S | C16: Safety | D16: Total Recordable Incident Rate (TRIR) | E16: 1.69 | F16: W | G16: Rate per 200k hrs | H16: 2022 | I16: Company ESG Report | J16: Smurfit Kappa 2021 Sustainability Report | L16: 25 | M16: 15 | N16: =_xlfn.XLOOKUP(H16,'E Data_Inventory'!$H$3:$H$240,'E Data_Inventory'!N$3:N$240) -> 20 | O16: 20 | P16: =L16+M16+N16+O16 -> 80 | Q16: =IF(P16>=80,"✅ High Quality",IF(P16>=60,"🟡 Acceptable",IF(P16>=40,"⚠️ Use with Caution","🔴 Insufficient"))) -> ✅ High Quality
B17: S | C17: Safety | D17: Total Recordable Incident Rate (TRIR) | E17: 1.61 | F17: W | G17: Rate per 200k hrs | H17: 2021 | I17: Company ESG Report | J17: Smurfit Westrock 2024 Sustainability Report | L17: 25 | M17: 15 | N17: =_xlfn.XLOOKUP(H17,'E Data_Inventory'!$H$3:$H$240,'E Data_Inventory'!N$3:N$240) -> 5 | O17: 20 | P17: =L17+M17+N17+O17 -> 65 | Q17: =IF(P17>=80,"✅ High Quality",IF(P17>=60,"🟡 Acceptable",IF(P17>=40,"⚠️ Use with Caution","🔴 Insufficient"))) -> 🟡 Acceptable
B18: S | C18: Safety | D18: Total Recordable Incident Rate (TRIR) | E18: 1.56 | F18: W | G18: Rate per 200k hrs | H18: 2020 | I18: Company ESG Report | J18: Westrock 2022 Sustainability Report | L18: 25 | M18: 15 | N18: =_xlfn.XLOOKUP(H18,'E Data_Inventory'!$H$3:$H$240,'E Data_Inventory'!N$3:N$240) -> 5 | O18: 20 | P18: =L18+M18+N18+O18 -> 65 | Q18: =IF(P18>=80,"✅ High Quality",IF(P18>=60,"🟡 Acceptable",IF(P18>=40,"⚠️ Use with Caution","🔴 Insufficient"))) -> 🟡 Acceptable
B19: S | C19: Safety | D19: Total Recordable Incident Rate (TRIR) | E19: 1.68 | F19: W | G19: Rate per 200k hrs | H19: 2019 | I19: Company ESG Report | J19: Smurfit Kappa 2021 Sustainability Report | L19: 25 | M19: 15 | N19: =_xlfn.XLOOKUP(H19,'E Data_Inventory'!$H$3:$H$240,'E Data_Inventory'!N$3:N$240) -> 5 | O19: 20 | P19: =L19+M19+N19+O19 -> 65 | Q19: =IF(P19>=80,"✅ High Quality",IF(P19>=60,"🟡 Acceptable",IF(P19>=40,"⚠️ Use with Caution","🔴 Insufficient"))) -> 🟡 Acceptable
B20: S | C20: Workforce | D20: Total Number of Employees | E20: 50017 | F20: W | G20: Headcount | H20: 2024 | I20: Company ESG Report | J20: Smurfit Kappa 2022 Sustainability Report | L20: 25 | M20: 15 | N20: =_xlfn.XLOOKUP(H20,'E Data_Inventory'!$H$3:$H$240,'E Data_Inventory'!N$3:N$240) -> 25 | O20: 20 | P20: =L20+M20+N20+O20 -> 85 | Q20: =IF(P20>=80,"✅ High Quality",IF(P20>=60,"🟡 Acceptable",IF(P20>=40,"⚠️ Use with Caution","🔴 Insufficient"))) -> ✅ High Quality
