Workbook

Sheet Instructions
A1: LAB 2 — Carbon Footprint Calculator | GHG Protocol Framework
A2: ESG Analytics & Management · Session 4 · Week 2 · This workbook feeds directly into Lab 3 (Environmental Dashboard)
A4: WORKBOOK CONTENTS
A5: Sheet | B5: Purpose & What to Complete
A6: 📋 Instructions | B6: You are here
A7: Assumptions | B7: Central inputs: company name, reporting years, financial data, GWP factors — FILL THIS FIRST
A8: Scope 1 | B8: Direct emissions: combustion, fleet, process, fugitive sources — enter activity data
A9: Scope 2 | B9: Purchased energy: market-based AND location-based dual calculation
A10: Scope 3 | B10: Value chain emissions: 5 categories using spend-based and activity-based methods
A11: Summary & Intensity | B11: Auto-calculated totals, intensity ratios, scope breakdown — review after entering data
A12: Trend Analysis | B12: 3-year historical trend table and chart builder — enter prior year data
A13: Emission Factors | B13: Reference tables: EPA, DEFRA, IEA grid factors — DO NOT EDIT formulas here
A14: Assumptions | B14: Document every emission factor used, boundary decisions, and methodology notes
A16: STEP-BY-STEP GUIDE
A17: Step 1 | B17: Fill Assumptions sheet: company info, financial metrics, years, GWP values
A18: Step 2 | B18: Enter activity data in Scope 1 (fuel consumption by source)
A19: Step 3 | B19: Enter electricity/energy data in Scope 2 (both market and location-based)
A20: Step 4 | B20: Estimate Scope 3 for at least 3 categories in Scope 3 sheet
A21: Step 5 | B21: Check Summary & Intensity — all totals pull automatically via formulas
A22: Step 6 | B22: Enter 2 prior years of data in Trend Analysis to build the trend chart
A23: Step 7 | B23: Document all sources and decisions in Assumptions Log
A25: COLOR CODING
A26: Blue text / Yellow background | B26: Your inputs — cells you must fill in
A27: Black text / White background | B27: Calculated formulas — do not edit
A28: Green text / Light green background | B28: Cross-sheet references pulling from other sheets
A30: GHG PROTOCOL BOUNDARY REMINDER
A31: Operational Control | B31: Include 100% of emissions from operations you control (most common approach)
A32: Equity Share | B32: Include % of emissions proportional to your ownership stake
A33: Financial Control | B33: Include entities where you have financial control
A34: Your boundary choice → | B34: Document in Methodology your Assumptions
A36: KEY FORMULAS USED IN THIS WORKBOOK
A37: Scope 1 (combustion) | B37: Activity (units) × Emission Factor (kgCO₂e/unit) ÷ 1,000 = tCO₂e | C37: This is the standard way to convert fuel use into tonnes of CO₂e. Emission factors are usually in kgCO₂e per unit, so dividing by 1,000 converts to tonnes.
A38: Scope 2 (location) | B38: Electricity (MWh) × Grid EF (kgCO₂e/MWh) ÷ 1,000 = tCO₂e
A39: Scope 2 (market) | B39: Electricity (MWh) × Supplier/Residual EF (kgCO₂e/MWh) ÷ 1,000 = tCO₂e
A40: Scope 3 (spend) | B40: Supplier Spend ($) × EEIO Factor (kgCO₂e/$) ÷ 1,000 = tCO₂e | C40: This is the standard spend‑based method using Environmentally Extended Input‑Output (EEIO) factors. It’s commonly used when activity data isn’t available.
A41: Intensity (revenue) | B41: Total tCO₂e ÷ Revenue ($M) = tCO₂e per $M revenue | C41: Intensity ratios are flexible, but this is a common one.
A42: GWP conversion | B42: CH₄ mass × GWP_CH4 = CO₂e | N₂O mass × GWP_N2O = CO₂e | C42: This is exactly how methane (CH₄), nitrous oxide (N₂O), and other gases are converted to CO₂‑equivalent using IPCC global warming potentials.

Sheet Assumptions
A1: CENTRAL ASSUMPTIONS — Fill This Sheet First
A2: All other sheets reference these cells. Update here and the whole model recalculates.
A4: SECTION A — COMPANY INFORMATION
A9: Company Name | B9: Westrock Company | C9: Used in all sheet headers
A10: Industry / Sector | B10: Pulp, Paper and Packaging | C10: Affects SASB materiality and EF selection
A11: Primary Country of Operations | B11: USA | C11: Used to select default grid emission factor
A12: Reporting Year (Current) | B12: 2023 | C12: Year of primary data being analyzed
A13: Reporting Year (Prior 1) | B13: 2019 | C13: For trend analysis — enter in Trend sheet
A14: SECTION B — FINANCIAL METRICS (for Intensity Calculations)
A15: Annual Revenue (USD Millions) | C15: USD Millions | D15: Used to calculate carbon intensity per $M revenue
A16: Number of Employees (FTE) | C16: Headcount | D16: Used to calculate carbon intensity per employee
A17: Total Production Volume (units) | C17: Microsoft is a software, cloud, and services company; no consolidated production-volume metric is reported. | D17: For manufacturing companies — carbon per unit produced
A18: Floor Space / Facility Area | C18: Microsoft does not publicly disclose total facility area in aggregate. | D18: For real estate, retail — carbon per m²
A19: Revenue Unit Note | C19: Text | D19: Important: ensure revenue is in $M not $B
A21: SECTION C — GLOBAL WARMING POTENTIAL (GWP) FACTORS — IPCC AR6 (2021)
A22: These factors convert non-CO₂ gases to CO₂ equivalents. AR6 values shown (default). Change only if your regulatory regime requires AR5 or AR4.
A23: Gas | B23: Chemical | C23: AR6 GWP (100-yr) | D23: AR5 GWP (100-yr) | E23: Your Selection | F23: Source
A24: Carbon Dioxide | B24: CO₂ | C24: 1 | D24: 1 | E24: 1 | F24: IPCC AR6, 2021
A25: Methane (fossil) | B25: CH₄ | C25: 29.8 | D25: 25 | E25: 29.8 | F25: IPCC AR6 WGI Table 7.SM.7
A26: Methane (biogenic) | B26: CH₄ | C26: 27.9 | D26: 25 | E26: 27.9 | F26: IPCC AR6 WGI Table 7.SM.7
A27: Nitrous Oxide | B27: N₂O | C27: 273 | D27: 298 | E27: 273 | F27: IPCC AR6 WGI Table 7.SM.7
A28: HFC-134a (refrigerant) | B28: CH₂FCF₃ | C28: 1526 | D28: 1430 | E28: 1526 | F28: IPCC AR6
A29: SF₆ (electrical equipment) | B29: SF₆ | C29: 25200 | D29: 22800 | E29: 25200 | F29: IPCC AR6
A32: Fiscal Year | B32: Revenue (USD) | C32: Employees
A33: 2024 | B33: 245120 | C33: 228000
A34: 2023 | B34: 211980 | C34: 221000
A35: 2022 | B35: 198270 | C35: 221000
A36: 2021 | B36: 168090 | C36: 181000
A37: 2020 | B37: 143020 | C37: 163000

Sheet Emission Factors
A1: EMISSION FACTORS REFERENCE LIBRARY — EPA, DEFRA, IEA 2023
A2: Reference only — do not edit. Factors are pre-loaded into calculation sheets. Update annually.
A4: TABLE 1 — STATIONARY COMBUSTION FACTORS (EPA Center for Corporate Climate Leadership 2023)
A5: # | B5: Fuel Type | C5: Unit | D5: CO₂ EF (kgCO₂/unit) | E5: CH₄ EF (gCH₄/unit) | F5: N₂O EF (gN₂O/unit) | G5: Source
A6: 1 | B6: Natural Gas | C6: MMBtu | D6: 53.06 | E6: 1 | F6: 0.1 | G6: EPA 2023 Table 1
A7: 2 | B7: Natural Gas | C7: m³ | D7: 1.879 | E7: 0.0354 | F7: 0.00354 | G7: EPA 2023 (converted)
A8: 3 | B8: Propane | C8: Gallon | D8: 5.68 | E8: 0.226 | F8: 0.023 | G8: EPA 2023 Table 1
A9: 4 | B9: Diesel Fuel / Fuel Oil No.2 | C9: Gallon | D9: 10.21 | E9: 0.41 | F9: 0.08 | G9: EPA 2023 Table 1
A10: 5 | B10: Diesel Fuel / Fuel Oil No.2 | C10: Litre | D10: 2.663 | E10: 0.139 | F10: 0.014 | G10: EPA 2023 (converted)
A11: 6 | B11: Residual Fuel Oil (No. 6) | C11: Gallon | D11: 11.27 | E11: 0.48 | F11: 0.1 | G11: EPA 2023 Table 1
A12: 7 | B12: Residual Fuel Oil (No. 6) | C12: Litre | D12: 3.122 | E12: 0.139 | F12: 0.014 | G12: EPA 2023 (converted)
B13: Residual Fuel Oil (No. 6) | C13: MMBtu | D13: 75.1 | E13: 3 | F13: 0.6 | G13: EPA 2023 Table 1
A14: 8 | B14: LPG | C14: Gallon | D14: 5.68 | E14: 0.226 | F14: 0.023 | G14: EPA 2023 Table 1
A15: 9 | B15: LPG | C15: Litre | D15: 1.555 | E15: 0.0617 | F15: 0.0062 | G15: EPA 2023 (converted)
A16: 10 | B16: Coal — Bituminous | C16: Short Ton | D16: 2325 | E16: 274 | F16: 40 | G16: EPA 2023 Table 1
B17: Coal — Bituminous | C17: MMBtu | D17: 93.28 | E17: 11 | F17: 1.6 | G17: EPA 2023 Table 1
A18: 11 | B18: Coal — Sub-bituminous | C18: Short Ton | D18: 1676 | E18: 190 | F18: 28 | G18: EPA 2023 Table 1
A19: 12 | B19: Wood / Wood Waste | C19: Short Ton | D19: 1640 | E19: 300 | F19: 4 | G19: EPA 2023 Table 1
A20: 13 | B20: Municipal Solid Waste | C20: Short Ton | D20: 902 | E20: 318 | F20: 42 | G20: EPA 2023 Table 1
A21: 14 | B21: Biomas Fuel (Biodiesel) | C21: MMBtu | D21: 73.84 | E21: 1.1 | F21: 0.11 | G21: EPA 2023 Table 1
B22: Buinass Fuels Solid (Wood & Wood Residuals) | C22: MMBtu | D22: 93.8 | E22: 7.2 | F22: 3.6
G26: epa.gov/system/files/documents/2023-03/ghg_emission_factors_hub.pdf
A28: TABLE 2 — MOBILE COMBUSTION FACTORS (EPA 2023 / DEFRA 2023)
A29: # | B29: Fuel Type | C29: Unit | D29: CO₂ EF (kgCO₂/unit) | E29: CH₄ EF (gCH₄/unit) | F29: N₂O EF (gN₂O/unit) | G29: Source
A30: 1 | B30: Gasoline — Passenger Cars | C30: Litre | D30: 2.312 | E30: 0.339 | F30: 0.033 | G30: DEFRA 2023 / (2.35) EPA 2023
A31: 2 | B31: Gasoline — Light-Duty Trucks | C31: Litre | D31: 2.312 | E31: 0.572 | F31: 0.057 | G31: DEFRA 2023 / EPA 2023
A32: 3 | B32: Diesel — Passenger Cars | C32: Litre | D32: 2.68 | E32: 0.046 | F32: 0.184 | G32: DEFRA 2023 / (2.69) EPA
A33: 4 | B33: Diesel — Heavy-Duty Trucks | C33: Litre | D33: 2.68 | E33: 0.06 | F33: 0.252 | G33: DEFRA 2023
A34: 5 | B34: Aviation Fuel (Jet A / Jet A-1) | C34: Litre | D34: 2.553 | E34: 0 | F34: 0 | G34: DEFRA 2023 / (2.53) EPA
A35: 6 | B35: Compressed Natural Gas (CNG) | C35: GJ | D35: 50.3 | E35: 0 | F35: 0 | G35: EPA 2023 / (50.3) EPA
A36: 7 | B36: Liquefied Natural Gas (LNG) | C36: Litre | D36: 2.75 | E36: 0 | F36: 0 | G36: DEFRA 2023
A38: TABLE 3 — ELECTRICITY GRID EMISSION FACTORS (IEA 2023 / EPA eGRID 2023)
A39: # | B39: Country / Region / Grid | C39: kgCO₂e / MWh (Location-Based) | D39: Source | E39: Year | F39: Notes
A40: 1 | B40: US National Average | C40: ~380-400 | D40: EPA eGRID 2023 | E40: 2023 | F40: Covers all NERC regions
A41: 2 | B41: US — CAMX (California) | C41: 194 | D41: EPA eGRID 2023 | E41: 2023 | F41: High renewables
A42: 3 | B42: US — ERCOT (Texas) | C42: 333 | D42: EPA eGRID 2023 | E42: 2023 | F42: Natural gas heavy
A43: 4 | B43: US — RFC (PJM Interconnection) | C43: 271 | D43: EPA eGRID 2023 | E43: 2023 | F43: Northeast / Midwest
A44: 5 | B44: US — WECC (Mountain) | C44: 319 | D44: EPA eGRID 2023 | E44: 2023 | F44: Mountain states
A45: 6 | B45: Canada National Average | C45: 110-140 | D45: Environment Canada 2022 | E45: 2022 | F45: High hydro share
A46: 7 | B46: European Union Average | C46: 230-260 | D46: European Environment Agency 2022 | E46: 2022 | F46: Weighted average
...

Sheet Scope 1 S
A1: SCOPE 1 — DIRECT GHG EMISSIONS | GHG Protocol: All sources your organization directly controls
A2: Enter activity data (fuel consumed, distance driven, refrigerant leaked). Emission factors are pre-loaded from EPA/DEFRA tables.
A4: PART A — STATIONARY COMBUSTION (Boilers, Furnaces, Generators, Turbines)
A5: # | B5: Fuel Source | C5: Activity Quantity | D5: Activity Unit | E5: CO₂ EF (kgCO₂/unit) | F5: CH₄ EF (gCH₄/unit) | G5: N₂O EF (gN₂O/unit) | H5: CO₂ (tCO₂) | I5: CH₄ (tCO₂e) | J5: N₂O (tCO₂e) | K5: Total (tCO₂e) | L5: Reporting Year
A6: 1 | B6: Natural Gas | D6: MMBtu | E6: ='Emission Factors'!$D$6 -> 53.06 | F6: ='Emission Factors'!$E$6 -> 1 | G6: ='Emission Factors'!$F$6 -> 0.1 | H6: =C6*E6/1000 -> 0 | I6: =$C6*$F6*Assumptions!$E$25/1000000 -> 0 | J6: =$C6*G6*Assumptions!$E$27/1000000 -> 0 | K6: =SUM(H6:J6) -> 0 | L6: 2019
A7: 2 | B7: Residual Fuel Oil (No. 6) | D7: MMBtu | E7: 75.1 | F7: 3 | G7: 0.6 | H7: =C7*E7/1000 -> 0 | I7: =$C7*$F7*Assumptions!$E$25/1000000 -> 0 | J7: =$C7*G7*Assumptions!$E$27/1000000 -> 0 | K7: =SUM(H7:J7) -> 0 | L7: 2019
A8: 3 | B8: Coal — Bituminous | D8: MMBtu | E8: 93.28 | F8: 11 | G8: 1.6 | H8: =C8*E8/1000 -> 0 | I8: =$C8*$F8*Assumptions!$E$25/1000000 -> 0 | J8: =$C8*G8*Assumptions!$E$27/1000000 -> 0 | K8: =SUM(H8:J8) -> 0 | L8: 2019
A9: 4 | B9: BioFuels Solid (Wood & Wood Residuals) | D9: MMBtu | E9: 93.8 | F9: 7.2 | G9: 3.6 | H9: =C9*E9/1000 -> 0 | I9: =$C9*$F9*Assumptions!$E$25/1000000 -> 0 | J9: =$C9*G9*Assumptions!$E$27/1000000 -> 0 | K9: =SUM(H9:J9) -> 0 | L9: 2019
A10: 5 | B10: Natural Gas | D10: MMBtu | E10: ='Emission Factors'!$D$6 -> 53.06 | F10: ='Emission Factors'!$E$6 -> 1 | G10: ='Emission Factors'!$F$6 -> 0.1 | H10: =C10*E10/1000 -> 0 | I10: =$C10*$F10*Assumptions!$E$25/1000000 -> 0 | J10: =$C10*G10*Assumptions!$E$27/1000000 -> 0 | K10: =SUM(H10:J10) -> 0 | L10: 2020
A11: 6 | B11: Residual Fuel Oil (No. 6) | D11: MMBtu | E11: 75.1 | F11: 3 | G11: 0.6 | H11: =C11*E11/1000 -> 0 | I11: =$C11*$F11*Assumptions!$E$25/1000000 -> 0 | J11: =$C11*G11*Assumptions!$E$27/1000000 -> 0 | K11: =SUM(H11:J11) -> 0 | L11: 2020
A12: 7 | B12: Coal — Bituminous | D12: MMBtu | E12: 93.28 | F12: 11 | G12: 1.6 | H12: =C12*E12/1000 -> 0 | I12: =$C12*$F12*Assumptions!$E$25/1000000 -> 0 | J12: =$C12*G12*Assumptions!$E$27/1000000 -> 0 | K12: =SUM(H12:J12) -> 0 | L12: 2020
A13: 8 | B13: BioFuels Solid (Wood & Wood Residuals) | D13: MMBtu | E13: 93.8 | F13: 7.2 | G13: 3.6 | H13: =C13*E13/1000 -> 0 | I13: =$C13*$F13*Assumptions!$E$25/1000000 -> 0 | J13: =$C13*G13*Assumptions!$E$27/1000000 -> 0 | K13: =SUM(H13:J13) -> 0 | L13: 2020
A14: 1 | B14: Natural Gas | D14: MMBtu | E14: ='Emission Factors'!$D$6 -> 53.06 | F14: ='Emission Factors'!$E$6 -> 1 | G14: ='Emission Factors'!$F$6 -> 0.1 | H14: =C14*E14/1000 -> 0 | I14: =$C14*$F14*Assumptions!$E$25/1000000 -> 0 | J14: =$C14*G14*Assumptions!$E$27/1000000 -> 0 | K14: =SUM(H14:J14) -> 0 | L14: 2021
A15: 2 | B15: Residual Fuel Oil (No. 6) | D15: MMBtu | E15: 75.1 | F15: 3 | G15: 0.6 | H15: =C15*E15/1000 -> 0 | I15: =$C15*$F15*Assumptions!$E$25/1000000 -> 0 | J15: =$C15*G15*Assumptions!$E$27/1000000 -> 0 | K15: =SUM(H15:J15) -> 0 | L15: 2021
A16: 3 | B16: Coal — Bituminous | D16: MMBtu | E16: 93.28 | F16: 11 | G16: 1.6 | H16: =C16*E16/1000 -> 0 | I16: =$C16*$F16*Assumptions!$E$25/1000000 -> 0 | J16: =$C16*G16*Assumptions!$E$27/1000000 -> 0 | K16: =SUM(H16:J16) -> 0 | L16: 2021
A17: 4 | B17: BioFuels Solid (Wood & Wood Residuals) | D17: MMBtu | E17: 93.8 | F17: 7.2 | G17: 3.6 | H17: =C17*E17/1000 -> 0 | I17: =$C17*$F17*Assumptions!$E$25/1000000 -> 0 | J17: =$C17*G17*Assumptions!$E$27/1000000 -> 0 | K17: =SUM(H17:J17) -> 0 | L17: 2021
A18: 5 | B18: Natural Gas | D18: MMBtu | E18: ='Emission Factors'!D2 -> 0 | F18: ='Emission Factors'!E2 -> 0 | G18: ='Emission Factors'!F2 -> 0 | H18: =C18*E18/1000 -> 0 | I18: =$C18*$F18*Assumptions!$E$25/1000000 -> 0 | J18: =$C18*G18*Assumptions!$E$27/1000000 -> 0 | K18: =SUM(H18:J18) -> 0 | L18: 2022
A19: 6 | B19: Residual Fuel Oil (No. 6) | D19: MMBtu | E19: 75.1 | F19: 3 | G19: 0.6 | H19: =C19*E19/1000 -> 0 | I19: =$C19*$F19*Assumptions!$E$25/1000000 -> 0 | J19: =$C19*G19*Assumptions!$E$27/1000000 -> 0 | K19: =SUM(H19:J19) -> 0 | L19: 2022
A20: 7 | B20: Coal — Bituminous | D20: MMBtu | E20: 93.28 | F20: 11 | G20: 1.6 | H20: =C20*E20/1000 -> 0 | I20: =$C20*$F20*Assumptions!$E$25/1000000 -> 0 | J20: =$C20*G20*Assumptions!$E$27/1000000 -> 0 | K20: =SUM(H20:J20) -> 0 | L20: 2022
A21: 8 | B21: BioFuels Solid (Wood & Wood Residuals) | D21: MMBtu | E21: 93.8 | F21: 7.2 | G21: 3.6 | H21: =C21*E21/1000 -> 0 | I21: =$C21*$F21*Assumptions!$E$25/1000000 -> 0 | J21: =$C21*G21*Assumptions!$E$27/1000000 -> 0 | K21: =SUM(H21:J21) -> 0 | L21: 2022
A22: 1 | B22: Natural Gas | C22: 11165284 | D22: MMBtu | E22: ='Emission Factors'!D6 -> 53.06 | F22: ='Emission Factors'!E6 -> 1 | G22: ='Emission Factors'!F6 -> 0.1 | H22: =C22*E22/1000 -> 592429.98 | I22: =$C22*$F22*Assumptions!$E$25/1000000 -> 332.72547 | J22: =$C22*G22*Assumptions!$E$27/1000000 -> 304.81226 | K22: =SUM(H22:J22) -> 593067.52 | L22: 2023
A23: 2 | B23: Residual Fuel Oil (No. 6) | D23: MMBtu | E23: 75.1 | F23: 3 | G23: 0.6 | H23: =C23*E23/1000 -> 0 | I23: =$C23*$F23*Assumptions!$E$25/1000000 -> 0 | J23: =$C23*G23*Assumptions!$E$27/1000000 -> 0 | K23: =SUM(H23:J23) -> 0 | L23: 2023
A24: 3 | B24: Coal — Bituminous | C24: 635037.39 | D24: MMBtu | E24: 93.28 | F24: 11 | G24: 1.6 | H24: =C24*E24/1000 -> 59236.288 | I24: =$C24*$F24*Assumptions!$E$25/1000000 -> 208.16526 | J24: =$C24*G24*Assumptions!$E$27/1000000 -> 277.38433 | K24: =SUM(H24:J24) -> 59721.837 | L24: 2023
A25: 4 | B25: BioFuels Solid (Wood & Wood Residuals) | C25: 12928224 | D25: MMBtu | E25: 93.8 | F25: 7.2 | G25: 3.6 | H25: =C25*E25/1000 -> 1212667.4 | I25: =$C25*$F25*Assumptions!$E$25/1000000 -> 2773.8797 | J25: =$C25*G25*Assumptions!$E$27/1000000 -> 12705.858 | K25: =SUM(H25:J25) -> 1228147.1 | L25: 2023
A26: 5 | B26: Natural Gas | C26: 10814592 | D26: MMBtu | E26: ='Emission Factors'!D10 -> 2.663 | F26: ='Emission Factors'!E10 -> 0.139 | G26: ='Emission Factors'!F10 -> 0.014 | H26: =C26*E26/1000 -> 28799.258 | I26: =$C26*$F26*Assumptions!$E$25/1000000 -> 44.796203 | J26: =$C26*G26*Assumptions!$E$27/1000000 -> 41.333371 | K26: =SUM(H26:J26) -> 28885.388 | L26: 2024
A27: 6 | B27: Residual Fuel Oil (No. 6) | D27: MMBtu | E27: 75.1 | F27: 3 | G27: 0.6 | H27: =C27*E27/1000 -> 0 | I27: =$C27*$F27*Assumptions!$E$25/1000000 -> 0 | J27: =$C27*G27*Assumptions!$E$27/1000000 -> 0 | K27: =SUM(H27:J27) -> 0 | L27: 2024
A28: 7 | B28: Coal — Bituminous | C28: 388604.97 | D28: MMBtu | E28: 93.28 | F28: 11 | G28: 1.6 | H28: =C28*E28/1000 -> 36249.072 | I28: =$C28*$F28*Assumptions!$E$25/1000000 -> 127.38471 | J28: =$C28*G28*Assumptions!$E$27/1000000 -> 169.74265 | K28: =SUM(H28:J28) -> 36546.199 | L28: 2024
A29: 8 | B29: BioFuels Solid (Wood & Wood Residuals) | C29: 13127265 | D29: MMBtu | E29: 93.8 | F29: 7.2 | G29: 3.6 | H29: =C29*E29/1000 -> 1231337.5 | I29: =$C29*$F29*Assumptions!$E$25/1000000 -> 2816.5861 | J29: =$C29*G29*Assumptions!$E$27/1000000 -> 12901.476 | K29: =SUM(H29:J29) -> 1247055.6 | L29: 2024
B30: SUBTOTAL — Stationary Combustion | H30: =SUM(H22:H29) -> 3160719.5 | I30: =SUM(I22:I29) -> 6303.5374 | J30: =SUM(J22:J29) -> 26400.608 | K30: =SUM(K22:K29) -> 3193423.6
A32: PART B — MOBILE COMBUSTION (Company Fleet, Owned/Leased Vehicles)
A33: # | B33: Fuel Source g | C33: Activity Quantity | D33: Activity Unit | E33: CO₂ EF (kgCO₂/unit) | F33: CH₄ EF (gCH₄/unit) | G33: N₂O EF (gN₂O/unit) | H33: CO₂ (tCO₂) | I33: CH₄ (tCO₂e) | J33: N₂O (tCO₂e) | K33: Total (tCO₂e)
A34: 1 | B34: Gasoline / Petrol (Passenger Cars) | D34: Litres | E34: 2.35 | F34: 0.1 | G34: 0.02 | H34: =C34*E34/1000 -> 0 | I34: =C34*F34/1000000*Assumptions!E25*1000 -> 0 | J34: =C34*G34/1000000*Assumptions!E27*1000 -> 0 | K34: =H34+I34+J34 -> 0
A35: 2 | B35: Gasoline / Petrol (Heavy-Duty Trucks) | D35: Litres | E35: 2.35 | F35: 0.1 | G35: 0.02 | H35: =C35*E35/1000 -> 0 | I35: =C35*F35/1000000*Assumptions!E25*1000 -> 0 | J35: =C35*G35/1000000*Assumptions!E27*1000 -> 0 | K35: =H35+I35+J35 -> 0
A36: 3 | B36: Diesel (Passenger Cars) | D36: Litres | E36: 2.69 | F36: 0.11 | G36: 0.02 | H36: =C36*E36/1000 -> 0 | I36: =C36*F36/1000000*Assumptions!E25*1000 -> 0 | J36: =C36*G36/1000000*Assumptions!E27*1000 -> 0 | K36: =H36+I36+J36 -> 0
A37: 4 | B37: Diesel (Heavy-Duty Trucks) | D37: Litres | E37: 2.69 | F37: 0.11 | G37: 0.02 | H37: =C37*E37/1000 -> 0 | I37: =C37*F37/1000000*Assumptions!E25*1000 -> 0 | J37: =C37*G37/1000000*Assumptions!E27*1000 -> 0 | K37: =H37+I37+J37 -> 0
A38: 5 | B38: Compressed Natural Gas (CNG) | D38: GJ | E38: 56.1 | F38: 0.95 | G38: 0.1 | H38: =C38*E38/1000 -> 0 | I38: =C38*F38/1000000*Assumptions!E25*1000 -> 0 | J38: =C38*G38/1000000*Assumptions!E27*1000 -> 0 | K38: =H38+I38+J38 -> 0
A39: 6 | B39: Aviation Fuel (Jet-A) | D39: Litres | E39: 2.54 | F39: 0.11 | G39: 0.02 | H39: =C39*E39/1000 -> 0 | I39: =C39*F39/1000000*Assumptions!E25*1000 -> 0 | J39: =C39*G39/1000000*Assumptions!E27*1000 -> 0 | K39: =H39+I39+J39 -> 0
A40: 7 | B40: Other / Specify | D40: Specify unit | E40: 0 | F40: 0 | G40: 0 | H40: =C40*E40/1000 -> 0 | I40: =C40*F40/1000000*Assumptions!E25*1000 -> 0 | J40: =C40*G40/1000000*Assumptions!E27*1000 -> 0 | K40: =H40+I40+J40 -> 0
B41: SUBTOTAL — Mobile Combustion | H41: =SUM(H34:H40) -> 0 | I41: =SUM(I34:I40) -> 0 | J41: =SUM(J34:J40) -> 0 | K41: =SUM(K34:K40) -> 0
A43: PART C — FUGITIVE EMISSIONS (Refrigerants, Methane Leaks, SF₆)
...

Sheet Scope 1 W
A1: SCOPE 1 — DIRECT GHG EMISSIONS | GHG Protocol: All sources your organization directly controls
A2: Enter activity data (fuel consumed, distance driven, refrigerant leaked). Emission factors are pre-loaded from EPA/DEFRA tables.
A4: PART A — STATIONARY COMBUSTION (Boilers, Furnaces, Generators, Turbines)
A5: # | B5: Fuel Source | C5: Activity Quantity | D5: Activity Unit | E5: CO₂ EF (kgCO₂/unit) | F5: CH₄ EF (gCH₄/unit) | G5: N₂O EF (gN₂O/unit) | H5: CO₂ (tCO₂) | I5: CH₄ (tCO₂e) | J5: N₂O (tCO₂e) | K5: Total (tCO₂e) | L5: Reporting Year
A6: 1 | B6: Natural Gas | D6: MMBtu | E6: ='Emission Factors'!$D$6 -> 53.06 | F6: ='Emission Factors'!$E$6 -> 1 | G6: ='Emission Factors'!$F$6 -> 0.1 | H6: =C6*E6/1000 -> 0 | I6: =$C6*$F6*Assumptions!$E$25/1000000 -> 0 | J6: =$C6*G6*Assumptions!$E$27/1000000 -> 0 | K6: =SUM(H6:J6) -> 0 | L6: 2019
A7: 2 | B7: Residual Fuel Oil (No. 6) | D7: MMBtu | E7: 75.1 | F7: 3 | G7: 0.6 | H7: =C7*E7/1000 -> 0 | I7: =$C7*$F7*Assumptions!$E$25/1000000 -> 0 | J7: =$C7*G7*Assumptions!$E$27/1000000 -> 0 | K7: =SUM(H7:J7) -> 0 | L7: 2019
A8: 3 | B8: Coal — Bituminous | D8: MMBtu | E8: 93.28 | F8: 11 | G8: 1.6 | H8: =C8*E8/1000 -> 0 | I8: =$C8*$F8*Assumptions!$E$25/1000000 -> 0 | J8: =$C8*G8*Assumptions!$E$27/1000000 -> 0 | K8: =SUM(H8:J8) -> 0 | L8: 2019
A9: 4 | B9: BioFuels Solid (Wood & Wood Residuals) | D9: MMBtu | E9: 93.8 | F9: 7.2 | G9: 3.6 | H9: =C9*E9/1000 -> 0 | I9: =$C9*$F9*Assumptions!$E$25/1000000 -> 0 | J9: =$C9*G9*Assumptions!$E$27/1000000 -> 0 | K9: =SUM(H9:J9) -> 0 | L9: 2019
A10: 5 | B10: Natural Gas | D10: MMBtu | E10: ='Emission Factors'!$D$6 -> 53.06 | F10: ='Emission Factors'!$E$6 -> 1 | G10: ='Emission Factors'!$F$6 -> 0.1 | H10: =C10*E10/1000 -> 0 | I10: =$C10*$F10*Assumptions!$E$25/1000000 -> 0 | J10: =$C10*G10*Assumptions!$E$27/1000000 -> 0 | K10: =SUM(H10:J10) -> 0 | L10: 2020
A11: 6 | B11: Residual Fuel Oil (No. 6) | D11: MMBtu | E11: 75.1 | F11: 3 | G11: 0.6 | H11: =C11*E11/1000 -> 0 | I11: =$C11*$F11*Assumptions!$E$25/1000000 -> 0 | J11: =$C11*G11*Assumptions!$E$27/1000000 -> 0 | K11: =SUM(H11:J11) -> 0 | L11: 2020
A12: 7 | B12: Coal — Bituminous | D12: MMBtu | E12: 93.28 | F12: 11 | G12: 1.6 | H12: =C12*E12/1000 -> 0 | I12: =$C12*$F12*Assumptions!$E$25/1000000 -> 0 | J12: =$C12*G12*Assumptions!$E$27/1000000 -> 0 | K12: =SUM(H12:J12) -> 0 | L12: 2020
A13: 8 | B13: BioFuels Solid (Wood & Wood Residuals) | D13: MMBtu | E13: 93.8 | F13: 7.2 | G13: 3.6 | H13: =C13*E13/1000 -> 0 | I13: =$C13*$F13*Assumptions!$E$25/1000000 -> 0 | J13: =$C13*G13*Assumptions!$E$27/1000000 -> 0 | K13: =SUM(H13:J13) -> 0 | L13: 2020
A14: 1 | B14: Natural Gas | D14: MMBtu | E14: ='Emission Factors'!$D$6 -> 53.06 | F14: ='Emission Factors'!$E$6 -> 1 | G14: ='Emission Factors'!$F$6 -> 0.1 | H14: =C14*E14/1000 -> 0 | I14: =$C14*$F14*Assumptions!$E$25/1000000 -> 0 | J14: =$C14*G14*Assumptions!$E$27/1000000 -> 0 | K14: =SUM(H14:J14) -> 0 | L14: 2021
A15: 2 | B15: Residual Fuel Oil (No. 6) | D15: MMBtu | E15: 75.1 | F15: 3 | G15: 0.6 | H15: =C15*E15/1000 -> 0 | I15: =$C15*$F15*Assumptions!$E$25/1000000 -> 0 | J15: =$C15*G15*Assumptions!$E$27/1000000 -> 0 | K15: =SUM(H15:J15) -> 0 | L15: 2021
A16: 3 | B16: Coal — Bituminous | D16: MMBtu | E16: 93.28 | F16: 11 | G16: 1.6 | H16: =C16*E16/1000 -> 0 | I16: =$C16*$F16*Assumptions!$E$25/1000000 -> 0 | J16: =$C16*G16*Assumptions!$E$27/1000000 -> 0 | K16: =SUM(H16:J16) -> 0 | L16: 2021
A17: 4 | B17: BioFuels Solid (Wood & Wood Residuals) | D17: MMBtu | E17: 93.8 | F17: 7.2 | G17: 3.6 | H17: =C17*E17/1000 -> 0 | I17: =$C17*$F17*Assumptions!$E$25/1000000 -> 0 | J17: =$C17*G17*Assumptions!$E$27/1000000 -> 0 | K17: =SUM(H17:J17) -> 0 | L17: 2021
A18: 5 | B18: Natural Gas | D18: MMBtu | E18: ='Emission Factors'!D2 -> 0 | F18: ='Emission Factors'!E2 -> 0 | G18: ='Emission Factors'!F2 -> 0 | H18: =C18*E18/1000 -> 0 | I18: =$C18*$F18*Assumptions!$E$25/1000000 -> 0 | J18: =$C18*G18*Assumptions!$E$27/1000000 -> 0 | K18: =SUM(H18:J18) -> 0 | L18: 2022
A19: 6 | B19: Residual Fuel Oil (No. 6) | D19: MMBtu | E19: 75.1 | F19: 3 | G19: 0.6 | H19: =C19*E19/1000 -> 0 | I19: =$C19*$F19*Assumptions!$E$25/1000000 -> 0 | J19: =$C19*G19*Assumptions!$E$27/1000000 -> 0 | K19: =SUM(H19:J19) -> 0 | L19: 2022
A20: 7 | B20: Coal — Bituminous | D20: MMBtu | E20: 93.28 | F20: 11 | G20: 1.6 | H20: =C20*E20/1000 -> 0 | I20: =$C20*$F20*Assumptions!$E$25/1000000 -> 0 | J20: =$C20*G20*Assumptions!$E$27/1000000 -> 0 | K20: =SUM(H20:J20) -> 0 | L20: 2022
A21: 8 | B21: BioFuels Solid (Wood & Wood Residuals) | D21: MMBtu | E21: 93.8 | F21: 7.2 | G21: 3.6 | H21: =C21*E21/1000 -> 0 | I21: =$C21*$F21*Assumptions!$E$25/1000000 -> 0 | J21: =$C21*G21*Assumptions!$E$27/1000000 -> 0 | K21: =SUM(H21:J21) -> 0 | L21: 2022
A22: 1 | B22: Natural Gas | C22: 86064639 | D22: MMBtu | E22: ='Emission Factors'!$D$6 -> 53.06 | F22: ='Emission Factors'!$E$6 -> 1 | G22: ='Emission Factors'!$F$6 -> 0.1 | H22: =C22*E22/1000 -> 4566589.7 | I22: =$C22*$F22*Assumptions!$E$25/1000000 -> 2564.7262 | J22: =$C22*G22*Assumptions!$E$27/1000000 -> 2349.5646 | K22: =SUM(H22:J22) -> 4571504 | L22: 2023
A23: 2 | B23: Residual Fuel Oil (No. 6) | C23: 1890395 | D23: MMBtu | E23: 75.1 | F23: 3 | G23: 0.6 | H23: =C23*E23/1000 -> 141968.66 | I23: =$C23*$F23*Assumptions!$E$25/1000000 -> 169.00131 | J23: =$C23*G23*Assumptions!$E$27/1000000 -> 309.6467 | K23: =SUM(H23:J23) -> 142447.31 | L23: 2023
A24: 3 | B24: Coal — Bituminous | C24: 14017876 | D24: MMBtu | E24: 93.28 | F24: 11 | G24: 1.6 | H24: =C24*E24/1000 -> 1307587.5 | I24: =$C24*$F24*Assumptions!$E$25/1000000 -> 4595.0598 | J24: =$C24*G24*Assumptions!$E$27/1000000 -> 6123.0082 | K24: =SUM(H24:J24) -> 1318305.5 | L24: 2023
A25: 4 | B25: BioFuels Solid (Wood & Wood Residuals) | C25: 166526977 | D25: MMBtu | E25: 93.8 | F25: 7.2 | G25: 3.6 | H25: =C25*E25/1000 -> 15620230 | I25: =$C25*$F25*Assumptions!$E$25/1000000 -> 35730.028 | J25: =$C25*G25*Assumptions!$E$27/1000000 -> 163662.71 | K25: =SUM(H25:J25) -> 15819623 | L25: 2023
A26: 5 | B26: Natural Gas | C26: 86013345 | D26: MMBtu | E26: ='Emission Factors'!D10 -> 2.663 | F26: ='Emission Factors'!E10 -> 0.139 | G26: ='Emission Factors'!F10 -> 0.014 | H26: =C26*E26/1000 -> 229053.54 | I26: =$C26*$F26*Assumptions!$E$25/1000000 -> 356.28448 | J26: =$C26*G26*Assumptions!$E$27/1000000 -> 328.743 | K26: =SUM(H26:J26) -> 229738.57 | L26: 2024
A27: 6 | B27: Residual Fuel Oil (No. 6) | C27: 1316148 | D27: MMBtu | E27: 75.1 | F27: 3 | G27: 0.6 | H27: =C27*E27/1000 -> 98842.715 | I27: =$C27*$F27*Assumptions!$E$25/1000000 -> 117.66363 | J27: =$C27*G27*Assumptions!$E$27/1000000 -> 215.58504 | K27: =SUM(H27:J27) -> 99175.963 | L27: 2024
A28: 7 | B28: Coal — Bituminous | C28: 9748199 | D28: MMBtu | E28: 93.28 | F28: 11 | G28: 1.6 | H28: =C28*E28/1000 -> 909312 | I28: =$C28*$F28*Assumptions!$E$25/1000000 -> 3195.4596 | J28: =$C28*G28*Assumptions!$E$27/1000000 -> 4258.0133 | K28: =SUM(H28:J28) -> 916765.48 | L28: 2024
A29: 8 | B29: BioFuels Solid (Wood & Wood Residuals) | C29: 160000000 | D29: MMBtu | E29: 93.8 | F29: 7.2 | G29: 3.6 | H29: =C29*E29/1000 -> 15008000 | I29: =$C29*$F29*Assumptions!$E$25/1000000 -> 34329.6 | J29: =$C29*G29*Assumptions!$E$27/1000000 -> 157248 | K29: =SUM(H29:J29) -> 15199578 | L29: 2024
B30: SUBTOTAL — Stationary Combustion | H30: =SUM(H22:H29) -> 37881585 | I30: =SUM(I22:I29) -> 81057.823 | J30: =SUM(J22:J29) -> 334495.27 | K30: =SUM(K22:K29) -> 38297138
A32: PART B — MOBILE COMBUSTION (Company Fleet, Owned/Leased Vehicles)
A33: # | B33: Fuel Source g | C33: Activity Quantity | D33: Activity Unit | E33: CO₂ EF (kgCO₂/unit) | F33: CH₄ EF (gCH₄/unit) | G33: N₂O EF (gN₂O/unit) | H33: CO₂ (tCO₂) | I33: CH₄ (tCO₂e) | J33: N₂O (tCO₂e) | K33: Total (tCO₂e)
A34: 1 | B34: Gasoline / Petrol (Passenger Cars) | D34: Litres | E34: 2.35 | F34: 0.1 | G34: 0.02 | H34: =C34*E34/1000 -> 0 | I34: =C34*F34/1000000*Assumptions!E25*1000 -> 0 | J34: =C34*G34/1000000*Assumptions!E27*1000 -> 0 | K34: =H34+I34+J34 -> 0
A35: 2 | B35: Gasoline / Petrol (Heavy-Duty Trucks) | D35: Litres | E35: 2.35 | F35: 0.1 | G35: 0.02 | H35: =C35*E35/1000 -> 0 | I35: =C35*F35/1000000*Assumptions!E25*1000 -> 0 | J35: =C35*G35/1000000*Assumptions!E27*1000 -> 0 | K35: =H35+I35+J35 -> 0
A36: 3 | B36: Diesel (Passenger Cars) | D36: Litres | E36: 2.69 | F36: 0.11 | G36: 0.02 | H36: =C36*E36/1000 -> 0 | I36: =C36*F36/1000000*Assumptions!E25*1000 -> 0 | J36: =C36*G36/1000000*Assumptions!E27*1000 -> 0 | K36: =H36+I36+J36 -> 0
A37: 4 | B37: Diesel (Heavy-Duty Trucks) | D37: Litres | E37: 2.69 | F37: 0.11 | G37: 0.02 | H37: =C37*E37/1000 -> 0 | I37: =C37*F37/1000000*Assumptions!E25*1000 -> 0 | J37: =C37*G37/1000000*Assumptions!E27*1000 -> 0 | K37: =H37+I37+J37 -> 0
A38: 5 | B38: Compressed Natural Gas (CNG) | D38: GJ | E38: 56.1 | F38: 0.95 | G38: 0.1 | H38: =C38*E38/1000 -> 0 | I38: =C38*F38/1000000*Assumptions!E25*1000 -> 0 | J38: =C38*G38/1000000*Assumptions!E27*1000 -> 0 | K38: =H38+I38+J38 -> 0
A39: 6 | B39: Aviation Fuel (Jet-A) | D39: Litres | E39: 2.54 | F39: 0.11 | G39: 0.02 | H39: =C39*E39/1000 -> 0 | I39: =C39*F39/1000000*Assumptions!E25*1000 -> 0 | J39: =C39*G39/1000000*Assumptions!E27*1000 -> 0 | K39: =H39+I39+J39 -> 0
A40: 7 | B40: Other / Specify | D40: Specify unit | E40: 0 | F40: 0 | G40: 0 | H40: =C40*E40/1000 -> 0 | I40: =C40*F40/1000000*Assumptions!E25*1000 -> 0 | J40: =C40*G40/1000000*Assumptions!E27*1000 -> 0 | K40: =H40+I40+J40 -> 0
B41: SUBTOTAL — Mobile Combustion | H41: =SUM(H34:H40) -> 0 | I41: =SUM(I34:I40) -> 0 | J41: =SUM(J34:J40) -> 0 | K41: =SUM(K34:K40) -> 0
A43: PART C — FUGITIVE EMISSIONS (Refrigerants, Methane Leaks, SF₆)
...

Sheet Scope 2 S
A1: SCOPE 2 — PURCHASED ENERGY | Dual Reporting: Market-Based AND Location-Based (GHG Protocol Required)
A2: GHG Protocol requires BOTH methods. Market-based reflects supplier contracts & RECs. Location-based uses grid averages.
A4: PART A — PURCHASED ELECTRICITY
A5: REFERENCE — Grid Emission Factors (kgCO₂e/MWh) | Source: IEA CO₂ Emissions from Fuel Combustion 2023 | CarbonFootprint.com (2025) Update annually
A6: Country/Region | B6: Grid EF (kgCO₂e/MWh)
A7: US Average | B7: 386 | C7: China | D7: 581
A8: US — California | B8: 230 | C8: India | D8: 713
A9: US — Texas (ERCOT) | B9: 430 | C9: Japan | D9: 471
A10: European Union Avg | B10: 231 | C10: Australia | D10: 680
A11: United Kingdom | B11: 207 | C11: Brazil | D11: 119
A12: Germany | B12: 380 | C12: Canada | D12: 130
A14: ELECTRICITY CONSUMPTION DATA
A15: # | B15: Facility / Region | C15: Electricity Consumed (MWh) | D15: Location-Based EF (kgCO₂/MWh) | E15: Market-Based EF (kgCO₂/MWh) | F15: RECs / PPAs (MWh covered) * | G15: Net Market- Based MWh | H15: Location-Based (tCO₂e) | I15: Market-Based (tCO₂e) | J15: Notes | K15: Reporting Year
A16: 1 | B16: Europe | C16: 0 | D16: 386 | E16: 0 | F16: 0 | G16: =MAX(C16-F16,0) -> 0 | H16: =C16*D16/1000 -> 0 | I16: =G16*E16/1000 -> 0 | J16: [Notes on EF source, REC details] | K16: 2019
A17: 2 | B17: The Americas | C17: 0 | D17: 386 | E17: 0 | F17: 0 | G17: =MAX(C17-F17,0) -> 0 | H17: =C17*D17/1000 -> 0 | I17: =G17*E17/1000 -> 0 | J17: [Notes on EF source, REC details] | K17: 2019
A18: 3 | B18: Europe | C18: 0 | D18: 386 | E18: 0 | F18: 0 | G18: =MAX(C18-F18,0) -> 0 | H18: =C18*D18/1000 -> 0 | I18: =G18*E18/1000 -> 0 | J18: [Notes on EF source, REC details] | K18: 2020
A19: 4 | B19: The Americas | C19: 0 | D19: 386 | E19: 0 | F19: 0 | G19: =MAX(C19-F19,0) -> 0 | H19: =C19*D19/1000 -> 0 | I19: =G19*E19/1000 -> 0 | J19: [Notes on EF source, REC details] | K19: 2020
A20: 1 | B20: Europe | C20: 0 | D20: 386 | E20: 0 | F20: 0 | G20: =MAX(C20-F20,0) -> 0 | H20: =C20*D20/1000 -> 0 | I20: =G20*E20/1000 -> 0 | J20: [Notes on EF source, REC details] | K20: 2021
A21: 2 | B21: The Americas | C21: 0 | D21: 386 | E21: 0 | F21: 0 | G21: =MAX(C21-F21,0) -> 0 | H21: =C21*D21/1000 -> 0 | I21: =G21*E21/1000 -> 0 | J21: [Notes on EF source, REC details] | K21: 2021
A22: 3 | B22: Europe | C22: 0 | D22: 386 | E22: 0 | F22: 0 | G22: =MAX(C22-F22,0) -> 0 | H22: =C22*D22/1000 -> 0 | I22: =G22*E22/1000 -> 0 | J22: [Notes on EF source, REC details] | K22: 2022
A23: 4 | B23: The Americas | C23: 0 | D23: 386 | E23: 0 | F23: 0 | G23: =MAX(C23-F23,0) -> 0 | H23: =C23*D23/1000 -> 0 | I23: =G23*E23/1000 -> 0 | J23: [Notes on EF source, REC details] | K23: 2022
A24: 1 | B24: Europe | C24: 0 | D24: 386 | E24: 0 | F24: 0 | G24: =MAX(C24-F24,0) -> 0 | H24: =C24*D24/1000 -> 0 | I24: =G24*E24/1000 -> 0 | J24: [Notes on EF source, REC details] | K24: 2024
A25: 2 | B25: The Americas | C25: 0 | D25: 386 | E25: 0 | F25: 0 | G25: =MAX(C25-F25,0) -> 0 | H25: =C25*D25/1000 -> 0 | I25: =G25*E25/1000 -> 0 | J25: [Notes on EF source, REC details] | K25: 2024
A26: 3 | B26: Europe | C26: 0 | D26: 386 | E26: 0 | F26: 0 | G26: =MAX(C26-F26,0) -> 0 | H26: =C26*D26/1000 -> 0 | I26: =G26*E26/1000 -> 0 | J26: [Notes on EF source, REC details] | K26: 2023
A27: 4 | B27: The Americas | C27: 0 | D27: 386 | E27: 0 | F27: 0 | G27: =MAX(C27-F27,0) -> 0 | H27: =C27*D27/1000 -> 0 | I27: =G27*E27/1000 -> 0 | J27: [Notes on EF source, REC details] | K27: 2023
A28: 5 | E28: 0 | F28: 0 | G28: =MAX(C28-F28,0) -> 0 | H28: =C28*D28/1000 -> 0 | I28: =G28*E28/1000 -> 0 | J28: [Notes on EF source, REC details]
A29: 6 | E29: 0 | F29: 0 | G29: =MAX(C29-F29,0) -> 0 | H29: =C29*D29/1000 -> 0 | I29: =G29*E29/1000 -> 0 | J29: [Notes on EF source, REC details]
A30: 7 | E30: 0 | F30: 0 | G30: =MAX(C30-F30,0) -> 0 | H30: =C30*D30/1000 -> 0 | I30: =G30*E30/1000 -> 0 | J30: [Notes on EF source, REC details]
B31: SUBTOTAL — Electricity | C31: 30207220 | F31: 29829540 | G31: =SUM(G24:G30) -> 0
A33: PART B — OTHER PURCHASED ENERGY (Steam, Heat, Cooling)
A34: # | B34: Energy Type | C34: Quantity Consumed | D34: Unit | E34: CO2 Factor (kg CO2 / mmBtu) | F34: CH4 Factor (g CH4 / mmBtu) | G34: N2O Factor (g N2O / mmBtu) | H34: Location-Based (tCO₂e) | I34: Market-Based (tCO₂e) | J34: Notes
A35: 1 | B35: Steam and Heat (Purchased) | D35: MMBtu | E35: 66.33 | F35: 1.25 | G35: 0.125 | H35: =((E35*C35)/1000)+((C35*F35*Assumptions!E25)/1000000)+(('Scope 2 S'!C35*'Scope 2 S'!G35*Assumptions!E27)/1000000) -> 0 | I35: =C35*E35/1000 -> 0 | J35: EPA Table 1
A36: 2 | B36: Steam and Heat (Sold) | D36: MMBtu | E36: 66.33 | F36: 1.25 | G36: 0.125 | H36: =C36*E36/1000 -> 0 | I36: =C36*E36/1000 -> 0 | J36: EPA Table 1
A37: 3 | C37: 0 | D37: GJ | E37: 66.4 | H37: =C37*E37/1000 -> 0 | I37: =C37*E37/1000 -> 0 | J37: [Source of emission factor]
B38: SUBTOTAL — Other Energy | H38: =((E35*C35)/1000)+((C35*F35*Assumptions!E25)/1000000)+('Scope 2 S'!C35*'Scope 2 S'!G35*Assumptions!E27)/1000000 -> 0 | I38: =SUM(I35:I37) -> 0
A40: ✦ SCOPE 2 TOTAL — LOCATION-BASED (tCO₂e) ✦ | H40: =H31+H38 -> 0
A41: ✦ SCOPE 2 TOTAL — MARKET-BASED (tCO₂e) [USE THIS FOR REPORTING] ✦ | I41: 0
A42: *(Renewable Energy Certificates) ; PPAs (Power Purchase Agreements) ; GOs (Guarantees of Origin, in Europe) ; I‑RECs (International RECs, global markets)
I44: Market | J44: Location | K44: ktons
H45: 2023 | K45: 467
...

Sheet Scope 2 W
A1: SCOPE 2 — PURCHASED ENERGY | Dual Reporting: Market-Based AND Location-Based (GHG Protocol Required)
A2: GHG Protocol requires BOTH methods. Market-based reflects supplier contracts & RECs. Location-based uses grid averages.
A4: PART A — PURCHASED ELECTRICITY
A5: REFERENCE — Grid Emission Factors (kgCO₂e/MWh) | Source: IEA CO₂ Emissions from Fuel Combustion 2023 | CarbonFootprint.com (2025) Update annually
A6: Country/Region | B6: Grid EF (kgCO₂e/MWh)
A7: US Average | B7: 386 | C7: China | D7: 581
A8: US — California | B8: 230 | C8: India | D8: 713
A9: US — Texas (ERCOT) | B9: 430 | C9: Japan | D9: 471
A10: European Union Avg | B10: 231 | C10: Australia | D10: 680
A11: United Kingdom | B11: 207 | C11: Brazil | D11: 119
A12: Germany | B12: 380 | C12: Canada | D12: 130
A14: ELECTRICITY CONSUMPTION DATA
A15: # | B15: Facility / Region | C15: Electricity Consumed (MWh) | D15: Location-Based EF (kgCO₂/MWh) | E15: Market-Based EF (kgCO₂/MWh) | F15: RECs / PPAs (MWh covered) * | G15: Net Market- Based MWh | H15: Location-Based (tCO₂e) | I15: Market-Based (tCO₂e) | J15: Notes | K15: Reporting Year
A16: 1 | B16: USA | C16: 1300000 | D16: 386 | E16: 0 | F16: 0 | G16: =MAX(C16-F16,0) -> 1300000 | H16: =C16*D16/1000 -> 501800 | I16: =G16*E16/1000 -> 0 | J16: [Notes on EF source, REC details] | K16: 2019
A17: 2 | B17: Canada | C17: 800000 | D17: 130 | E17: 0 | F17: 0 | G17: =MAX(C17-F17,0) -> 800000 | H17: =C17*D17/1000 -> 104000 | I17: =G17*E17/1000 -> 0 | J17: [Notes on EF source, REC details] | K17: 2019
A18: 3 | B18: Mexico | C18: 900000 | D18: 408 | E18: 0 | F18: 0 | G18: =MAX(C18-F18,0) -> 900000 | H18: =C18*D18/1000 -> 367200 | I18: =G18*E18/1000 -> 0 | J18: [Notes on EF source, REC details] | K18: 2019
A19: 4 | B19: Brazil | C19: 400000 | D19: 119 | E19: 0 | F19: 0 | G19: =MAX(C19-F19,0) -> 400000 | H19: =C19*D19/1000 -> 47600 | I19: =G19*E19/1000 -> 0 | J19: [Notes on EF source, REC details] | K19: 2019
A20: 5 | B20: Europe | C20: 200000 | D20: 250 | E20: 0 | F20: 0 | G20: =MAX(C20-F20,0) -> 200000 | H20: =C20*D20/1000 -> 50000 | I20: =G20*E20/1000 -> 0 | J20: [Notes on EF source, REC details] | K20: 2019
A21: 6 | B21: USA | C21: =C16*0.75 -> 975000 | D21: 386 | E21: 0 | F21: 0 | G21: =MAX(C21-F21,0) -> 975000 | H21: =C21*D21/1000 -> 376350 | I21: =G21*E21/1000 -> 0 | J21: [Notes on EF source, REC details] | K21: 2020
A22: 7 | B22: Canada | C22: =C17*0.75 -> 600000 | D22: 130 | E22: 0 | F22: 0 | G22: =MAX(C22-F22,0) -> 600000 | H22: =C22*D22/1000 -> 78000 | I22: =G22*E22/1000 -> 0 | J22: [Notes on EF source, REC details] | K22: 2020
A23: 8 | B23: Mexico | C23: =C18*0.75 -> 675000 | D23: 408 | E23: 0 | F23: 0 | G23: =MAX(C23-F23,0) -> 675000 | H23: =C23*D23/1000 -> 275400 | I23: =G23*E23/1000 -> 0 | J23: [Notes on EF source, REC details] | K23: 2020
A24: 9 | B24: Brazil | C24: =C19*0.75 -> 300000 | D24: 119 | E24: 0 | F24: 0 | G24: =MAX(C24-F24,0) -> 300000 | H24: =C24*D24/1000 -> 35700 | I24: =G24*E24/1000 -> 0 | J24: [Notes on EF source, REC details] | K24: 2020
A25: 10 | B25: Europe | C25: =C20*0.75 -> 150000 | D25: 250 | E25: 0 | F25: 0 | G25: =MAX(C25-F25,0) -> 150000 | H25: =C25*D25/1000 -> 37500 | I25: =G25*E25/1000 -> 0 | J25: [Notes on EF source, REC details] | K25: 2020
A26: 1 | B26: USA | C26: 1300000 | D26: 386 | E26: 0 | F26: 0 | G26: =MAX(C26-F26,0) -> 1300000 | H26: =C26*D26/1000 -> 501800 | I26: =G26*E26/1000 -> 0 | J26: [Notes on EF source, REC details] | K26: 2021
A27: 2 | B27: Canada | C27: 800000 | D27: 130 | E27: 0 | F27: 0 | G27: =MAX(C27-F27,0) -> 800000 | H27: =C27*D27/1000 -> 104000 | I27: =G27*E27/1000 -> 0 | J27: [Notes on EF source, REC details] | K27: 2021
A28: 3 | B28: Mexico | C28: 900000 | D28: 408 | E28: 0 | F28: 0 | G28: =MAX(C28-F28,0) -> 900000 | H28: =C28*D28/1000 -> 367200 | I28: =G28*E28/1000 -> 0 | J28: [Notes on EF source, REC details] | K28: 2021
A29: 4 | B29: Brazil | C29: 400000 | D29: 119 | E29: 0 | F29: 0 | G29: =MAX(C29-F29,0) -> 400000 | H29: =C29*D29/1000 -> 47600 | I29: =G29*E29/1000 -> 0 | J29: [Notes on EF source, REC details] | K29: 2021
A30: 5 | B30: Europe | C30: 200000 | D30: 250 | E30: 0 | F30: 0 | G30: =MAX(C30-F30,0) -> 200000 | H30: =C30*D30/1000 -> 50000 | I30: =G30*E30/1000 -> 0 | J30: [Notes on EF source, REC details] | K30: 2021
A31: 6 | B31: USA | C31: =C26*0.75 -> 975000 | D31: 386 | E31: 0 | F31: 0 | G31: =MAX(C31-F31,0) -> 975000 | H31: =C31*D31/1000 -> 376350 | I31: =G31*E31/1000 -> 0 | J31: [Notes on EF source, REC details] | K31: 2022
A32: 7 | B32: Canada | C32: =C27*0.75 -> 600000 | D32: 130 | E32: 0 | F32: 0 | G32: =MAX(C32-F32,0) -> 600000 | H32: =C32*D32/1000 -> 78000 | I32: =G32*E32/1000 -> 0 | J32: [Notes on EF source, REC details] | K32: 2022
A33: 8 | B33: Mexico | C33: =C28*0.75 -> 675000 | D33: 408 | E33: 0 | F33: 0 | G33: =MAX(C33-F33,0) -> 675000 | H33: =C33*D33/1000 -> 275400 | I33: =G33*E33/1000 -> 0 | J33: [Notes on EF source, REC details] | K33: 2022
A34: 9 | B34: Brazil | C34: =C29*0.75 -> 300000 | D34: 119 | E34: 0 | F34: 0 | G34: =MAX(C34-F34,0) -> 300000 | H34: =C34*D34/1000 -> 35700 | I34: =G34*E34/1000 -> 0 | J34: [Notes on EF source, REC details] | K34: 2022
A35: 10 | B35: Europe | C35: =C30*0.75 -> 150000 | D35: 250 | E35: 0 | F35: 0 | G35: =MAX(C35-F35,0) -> 150000 | H35: =C35*D35/1000 -> 37500 | I35: =G35*E35/1000 -> 0 | J35: [Notes on EF source, REC details] | K35: 2022
A36: 1 | B36: USA | C36: 1300000 | D36: 386 | E36: 0 | F36: 0 | G36: =MAX(C36-F36,0) -> 1300000 | H36: =C36*D36/1000 -> 501800 | I36: =G36*E36/1000 -> 0 | J36: [Notes on EF source, REC details] | K36: 2023
A37: 2 | B37: Canada | C37: 800000 | D37: 130 | E37: 0 | F37: 0 | G37: =MAX(C37-F37,0) -> 800000 | H37: =C37*D37/1000 -> 104000 | I37: =G37*E37/1000 -> 0 | J37: [Notes on EF source, REC details] | K37: 2023
A38: 3 | B38: Mexico | C38: 900000 | D38: 408 | E38: 0 | F38: 0 | G38: =MAX(C38-F38,0) -> 900000 | H38: =C38*D38/1000 -> 367200 | I38: =G38*E38/1000 -> 0 | J38: [Notes on EF source, REC details] | K38: 2023
A39: 4 | B39: Brazil | C39: 400000 | D39: 119 | E39: 0 | F39: 0 | G39: =MAX(C39-F39,0) -> 400000 | H39: =C39*D39/1000 -> 47600 | I39: =G39*E39/1000 -> 0 | J39: [Notes on EF source, REC details] | K39: 2023
A40: 5 | B40: Europe | C40: 200000 | D40: 250 | E40: 0 | F40: 0 | G40: =MAX(C40-F40,0) -> 200000 | H40: =C40*D40/1000 -> 50000 | I40: =G40*E40/1000 -> 0 | J40: [Notes on EF source, REC details] | K40: 2023
A41: 6 | B41: USA | C41: =C36*0.75 -> 975000 | D41: 386 | E41: 0 | F41: 0 | G41: =MAX(C41-F41,0) -> 975000 | H41: =C41*D41/1000 -> 376350 | I41: =G41*E41/1000 -> 0 | J41: [Notes on EF source, REC details] | K41: 2024
A42: 7 | B42: Canada | C42: =C37*0.75 -> 600000 | D42: 130 | E42: 0 | F42: 0 | G42: =MAX(C42-F42,0) -> 600000 | H42: =C42*D42/1000 -> 78000 | I42: =G42*E42/1000 -> 0 | J42: [Notes on EF source, REC details] | K42: 2024
...

Sheet Scope 3 S
A1: SCOPE 3 — VALUE CHAIN EMISSIONS | Cover at least 3 of the 15 categories most material to your industry
A2: Scope 3 typically represents 70–90% of total footprint. Use spend-based method where activity data is unavailable.
A4: SCOPE 3 CATEGORY OVERVIEW — Mark which categories are material for your company (✓ = Include, N/A = Not applicable)
B5: Cat # | C5: Category Name | D5: Stream | E5: Typical Method | F5: Material for your industry? | G5: Estimated % of S3 (Reasonable Industry averages) | H5: Notes: It is NOT an official GHG Protocol requirement
B6: 1 | C6: Purchased Goods & Services | D6: Upstream | E6: Spend-based or supplier-specific | F6: High for manufacturing/retail | G6: ~40% | H6: Often true, for manufacturing, retail, food, apparel, pharma — this is usually the largest Scope 3 category.
B7: 2 | C7: Capital Goods | D7: Upstream | E7: Spend-based | F7: High for capital-intensive industries | G7: ~5% | H7: Reasonable. Higher for construction, tech hardware, automotive; lower for services.
B8: 3 | C8: Fuel & Energy-Related Activities | D8: Upstream | E8: Activity-based | F8: ALL companies | G8: ~3% | H8: Typical. Usually small unless energy use is huge.
B9: 4 | C9: Upstream Transportation & Distribution | D9: Upstream | E9: Spend/distance-based | F9: Retail, manufacturing | G9: ~5% | H9: Reasonable. Retail, manufacturing, e‑commerce often fall in this range.
B10: 5 | C10: Waste Generated in Operations | D10: Upstream | E10: Activity-based | F10: Manufacturing, food & beverage | G10: ~1% | H10: Typical. Only large for food, agriculture, chemicals.
B11: 6 | C11: Business Travel | D11: Upstream | E11: Activity-based (km × EF) | F11: Services, consulting, financial | G11: ~1% | H11: Typical. Higher for consulting, finance, tech
B12: 7 | C12: Employee Commuting | D12: Upstream | E12: Survey-based | F12: Office-heavy companies | G12: ~1% | H12: Typical. Office-heavy companies
B13: 8 | C13: Upstream Leased Assets | D13: Upstream | E13: Asset-specific | F13: Companies with leased fleet/space | G13: ~2% | H13: Depends. Only relevant if you lease equipment or space.
B14: 9 | C14: Downstream Transportation | D14: Downstream | E14: Spend/distance-based | F14: Consumer goods, e-commerce | G14: ~5% | H14: Typical. Big for consumer goods and e‑commerce.
B15: 10 | C15: Processing of Sold Products | D15: Downstream | E15: Industry-specific | F15: Chemicals, materials suppliers | G15: ~3% | H15: Industry-specific. Chemicals, materials, components.
B16: 11 | C16: Use of Sold Products | D16: Downstream | E16: Activity-based (product use) | F16: High for electronics, vehicles, appliances | G16: ~25% | H16: Very common. Electronics, appliances, vehicles — often the largest category.
... B20: 15 | C20: Investments | D20: Downstream | E20: PCAF / portfolio-based | F20: Financial institutions, banks | G20: ~30% | H20: True for finance. Banks, PE, VC — this is usually the dominant category.
A23: CATEGORY 1 — PURCHASED GOODS & SERVICES (Spend-Based Method)
A24: # | B24: Supplier / Spend Category | C24: Annual Spend (USD) | D24: EEIO Factor (kgCO₂e per $)a | E24: Typical USEEIP Range b | F24: EEIO Source | G24: Spend in $000s | H24: Notes | J24: tCO₂e | K24: Data Confidence | L24: Notes
A25: 1 | B25: Raw Materials / Commodities | C25: 0 | D25: 0.35 | E25: 0.2 - 1.20 | F25: US EPA USEEIO v2.0 | H25: Plastics material & resin manufacturing; Steel mills; Paper mills | J25: =C25*D25/1000 -> 0 | K25: Medium | L25: [Enter data source / assumption]
A26: 2 | B26: Manufactured Components / Parts | C26: 0 | D26: 0.52 | E26: 0.4 - 1.50 | F26: US EPA USEEIO v2.0 | H26: Semiconductor manufacturing; Electronic component manufacturing; Fabricated metal products | J26: =C26*D26/1000 -> 0 | K26: Medium | L26: [Enter data source / assumption]
A27: 3 | B27: Packaging Materials | C27: 0 | D27: 0.63 | E27: 0.5 -1.00 | F27: US EPA USEEIO v2.0 | H27: Paperboard container manufacturing; Plastics packaging manufacturing | J27: =C27*D27/1000 -> 0 | K27: Medium | L27: [Enter data source / assumption]
A28: 4 | B28: Information Technology / Hardware | C28: 0 | D28: 0.85 | E28: 0.7 - 1.40 | F28: US EPA USEEIO v2.0 | H28: Computer manufacturing; Electronic equipment manufacturing | J28: =C28*D28/1000 -> 0 | K28: Medium | L28: [Enter data source / assumption]
A29: 5 | B29: Professional / Business Services | C29: 0 | D29: 0.12 | E29: 0.05 - 0.20 | F29: US EPA USEEIO v2.0 | H29: Management consulting services; Legal services; Accounting services | J29: =C29*D29/1000 -> 0 | K29: Medium | L29: [Enter data source / assumption]
A30: 6 | B30: Food & Beverage (for operations) | C30: 0 | D30: 0.95 | E30: 0.8 -1.60 | F30: US EPA USEEIO v2.0 | H30: Food manufacturing; Beverage manufacturing | J30: =C30*D30/1000 -> 0 | K30: Medium | L30: [Enter data source / assumption]
A31: 7 | B31: Construction / Building Materials | C31: 0 | D31: 0.42 | E31: 0.3 - 0 70 | F31: US EPA USEEIO v2.0 | H31: Cement manufacturing; Ready‑mix concrete; Construction services | J31: =C31*D31/1000 -> 0 | K31: Medium | L31: [Enter data source / assumption]
A32: 8 | B32: Other goods/services (specify) | C32: 0 | D32: 0.25 | E32: varies | J32: =C32*D32/1000 -> 0 | K32: Medium | L32: [Enter data source / assumption]
B33: SUBTOTAL — Category 1 | C33: =SUM(C25:C32) -> 0
B34: a EEIO = Environmentally Extended Input–Output. How many kg of CO₂e are emitted per dollar spent on a product or service.
B35: b Typical range of emission intensities (kgCO₂e per dollar spent) found across sectors in the USEEIO model — the U.S. Environmentally Extended Input–Output model published by the EPA.
A36: CATEGORY 3 — FUEL & ENERGY RELATED ACTIVITIES (Upstream Emissions from Purchased Energy)
A37: # | B37: Activity | C37: Scope 2 Electricity (MWh) | D37: T&D Loss Factor c (% of consumption) | E37: Well-to-Tank EF d (kgCO₂e/MWh) DEFRA | F37: Step 1 — Calculate T&D loss electricity | G37: Step 2 — Multiply by the DEFRA upstream electricity factor | H37: Step 3 — Convert to tonnes | I37: Emission Factor (EPA e grid) for subregion e.g. Chicago | J37: tCO₂e | K37: (tCO₂e for Category 3) tCO2e | L37: Confidence | M37: Notes
A38: 1 | B38: T&D Losses — Purchased Electricity | C38: 0 | D38: 0.042 | E38: 26.5 | F38: =C38*D38 -> 0 | G38: =F38*E38 -> 0 | H38: =G38/1000 -> 0 | I38: 416 | J38: =C38*D38*E38/1000 -> 0 | K38: =I38*F38/1000 -> 0 | M38: [Enter source]
A39: 2 | B39: Well-to-Tank — Natural Gas (for Scope 1) | C39: 0 | D39: 0 | E39: 15.4 | F39: =C39*D39 -> 0 | G39: =F39*E39 -> 0 | H39: =G39/1000 -> 0 | J39: =C39*E39/1000 -> 0 | M39: [Enter source]
A40: 3 | B40: Well-to-Tank — Diesel Fuel (for Scope 1) | C40: 0 | D40: 0 | E40: 16.7 | F40: =C40*D40 -> 0 | G40: =F40*E40 -> 0 | H40: =G40/1000 -> 0 | J40: =C40*E40/1000 -> 0 | M40: [Enter source]
A41: 4 | B41: Well-to-Tank — Gasoline (for Scope 1) | C41: 0 | D41: 0 | E41: 14.8 | F41: =C41*D41 -> 0 | G41: =F41*E41 -> 0 | H41: =G41/1000 -> 0 | J41: =C41*E41/1000 -> 0 | M41: [Enter source]
B42: SUBTOTAL — Category 3 | I42: * it was provided
B43: UK DEFRA/BEIS. EPA does not publish Well‑to‑Tank (WTT) emission factors for electricity or fuels.
B44: c T&D = Transmission & Distribution.
B45: d Upstream emissions from producing, processing, and delivering the fuel before it is used.
A46: CATEGORY 6 — BUSINESS TRAVEL (Activity-Based: Distance × Emission Factor)
...

Sheet Scope 3 W
A1: SCOPE 3 — VALUE CHAIN EMISSIONS | Cover at least 3 of the 15 categories most material to your industry
A2: Scope 3 typically represents 70–90% of total footprint. Use spend-based method where activity data is unavailable.
A4: SCOPE 3 CATEGORY OVERVIEW — Mark which categories are material for your company (✓ = Include, N/A = Not applicable)
B5: Cat # | C5: Category Name | D5: Stream | E5: Typical Method | F5: Material for your industry? | G5: Estimated % of S3 (Reasonable Industry averages) | H5: Notes: It is NOT an official GHG Protocol requirement
B6: 1 | C6: Purchased Goods & Services | D6: Upstream | E6: Spend-based or supplier-specific | F6: High for manufacturing/retail | G6: ~40% | H6: Often true, for manufacturing, retail, food, apparel, pharma — this is usually the largest Scope 3 category.
B7: 2 | C7: Capital Goods | D7: Upstream | E7: Spend-based | F7: High for capital-intensive industries | G7: ~5% | H7: Reasonable. Higher for construction, tech hardware, automotive; lower for services.
B8: 3 | C8: Fuel & Energy-Related Activities | D8: Upstream | E8: Activity-based | F8: ALL companies | G8: ~3% | H8: Typical. Usually small unless energy use is huge.
B9: 4 | C9: Upstream Transportation & Distribution | D9: Upstream | E9: Spend/distance-based | F9: Retail, manufacturing | G9: ~5% | H9: Reasonable. Retail, manufacturing, e‑commerce often fall in this range.
B10: 5 | C10: Waste Generated in Operations | D10: Upstream | E10: Activity-based | F10: Manufacturing, food & beverage | G10: ~1% | H10: Typical. Only large for food, agriculture, chemicals.
B11: 6 | C11: Business Travel | D11: Upstream | E11: Activity-based (km × EF) | F11: Services, consulting, financial | G11: ~1% | H11: Typical. Higher for consulting, finance, tech
B12: 7 | C12: Employee Commuting | D12: Upstream | E12: Survey-based | F12: Office-heavy companies | G12: ~1% | H12: Typical. Office-heavy companies
B13: 8 | C13: Upstream Leased Assets | D13: Upstream | E13: Asset-specific | F13: Companies with leased fleet/space | G13: ~2% | H13: Depends. Only relevant if you lease equipment or space.
B14: 9 | C14: Downstream Transportation | D14: Downstream | E14: Spend/distance-based | F14: Consumer goods, e-commerce | G14: ~5% | H14: Typical. Big for consumer goods and e‑commerce.
B15: 10 | C15: Processing of Sold Products | D15: Downstream | E15: Industry-specific | F15: Chemicals, materials suppliers | G15: ~3% | H15: Industry-specific. Chemicals, materials, components.
B16: 11 | C16: Use of Sold Products | D16: Downstream | E16: Activity-based (product use) | F16: High for electronics, vehicles, appliances | G16: ~25% | H16: Very common. Electronics, appliances, vehicles — often the largest category.
... B20: 15 | C20: Investments | D20: Downstream | E20: PCAF / portfolio-based | F20: Financial institutions, banks | G20: ~30% | H20: True for finance. Banks, PE, VC — this is usually the dominant category.
A23: CATEGORY 1 — PURCHASED GOODS & SERVICES (Spend-Based Method)
A24: # | B24: Supplier / Spend Category | C24: Annual Spend (USD) | D24: EEIO Factor (kgCO₂e per $)a | E24: Typical USEEIP Range b | F24: EEIO Source | G24: Spend in $000s | H24: Notes | J24: tCO₂e | K24: Data Confidence | L24: Notes
A25: 1 | B25: Raw Materials / Commodities | C25: 0 | D25: 0.35 | E25: 0.2 - 1.20 | F25: US EPA USEEIO v2.0 | H25: Plastics material & resin manufacturing; Steel mills; Paper mills | J25: =C25*D25/1000 -> 0 | K25: Medium | L25: [Enter data source / assumption]
A26: 2 | B26: Manufactured Components / Parts | C26: 0 | D26: 0.52 | E26: 0.4 - 1.50 | F26: US EPA USEEIO v2.0 | H26: Semiconductor manufacturing; Electronic component manufacturing; Fabricated metal products | J26: =C26*D26/1000 -> 0 | K26: Medium | L26: [Enter data source / assumption]
A27: 3 | B27: Packaging Materials | C27: 0 | D27: 0.63 | E27: 0.5 -1.00 | F27: US EPA USEEIO v2.0 | H27: Paperboard container manufacturing; Plastics packaging manufacturing | J27: =C27*D27/1000 -> 0 | K27: Medium | L27: [Enter data source / assumption]
A28: 4 | B28: Information Technology / Hardware | C28: 0 | D28: 0.85 | E28: 0.7 - 1.40 | F28: US EPA USEEIO v2.0 | H28: Computer manufacturing; Electronic equipment manufacturing | J28: =C28*D28/1000 -> 0 | K28: Medium | L28: [Enter data source / assumption]
A29: 5 | B29: Professional / Business Services | C29: 0 | D29: 0.12 | E29: 0.05 - 0.20 | F29: US EPA USEEIO v2.0 | H29: Management consulting services; Legal services; Accounting services | J29: =C29*D29/1000 -> 0 | K29: Medium | L29: [Enter data source / assumption]
A30: 6 | B30: Food & Beverage (for operations) | C30: 0 | D30: 0.95 | E30: 0.8 -1.60 | F30: US EPA USEEIO v2.0 | H30: Food manufacturing; Beverage manufacturing | J30: =C30*D30/1000 -> 0 | K30: Medium | L30: [Enter data source / assumption]
A31: 7 | B31: Construction / Building Materials | C31: 0 | D31: 0.42 | E31: 0.3 - 0 70 | F31: US EPA USEEIO v2.0 | H31: Cement manufacturing; Ready‑mix concrete; Construction services | J31: =C31*D31/1000 -> 0 | K31: Medium | L31: [Enter data source / assumption]
A32: 8 | B32: Other goods/services (specify) | C32: 0 | D32: 0.25 | E32: varies | J32: =C32*D32/1000 -> 0 | K32: Medium | L32: [Enter data source / assumption]
B33: SUBTOTAL — Category 1 | C33: =SUM(C25:C32) -> 0
B34: a EEIO = Environmentally Extended Input–Output. How many kg of CO₂e are emitted per dollar spent on a product or service.
B35: b Typical range of emission intensities (kgCO₂e per dollar spent) found across sectors in the USEEIO model — the U.S. Environmentally Extended Input–Output model published by the EPA.
A36: CATEGORY 3 — FUEL & ENERGY RELATED ACTIVITIES (Upstream Emissions from Purchased Energy)
A37: # | B37: Activity | C37: Scope 2 Electricity (MWh) | D37: T&D Loss Factor c (% of consumption) | E37: Well-to-Tank EF d (kgCO₂e/MWh) DEFRA | F37: Step 1 — Calculate T&D loss electricity | G37: Step 2 — Multiply by the DEFRA upstream electricity factor | H37: Step 3 — Convert to tonnes | I37: Emission Factor (EPA e grid) for subregion e.g. Chicago | J37: tCO₂e | K37: (tCO₂e for Category 3) tCO2e | L37: Confidence | M37: Notes
A38: 1 | B38: T&D Losses — Purchased Electricity | C38: 0 | D38: 0.042 | E38: 26.5 | F38: =C38*D38 -> 0 | G38: =F38*E38 -> 0 | H38: =G38/1000 -> 0 | I38: 416 | J38: =C38*D38*E38/1000 -> 0 | K38: =I38*F38/1000 -> 0 | M38: [Enter source]
A39: 2 | B39: Well-to-Tank — Natural Gas (for Scope 1) | C39: 0 | D39: 0 | E39: 15.4 | F39: =C39*D39 -> 0 | G39: =F39*E39 -> 0 | H39: =G39/1000 -> 0 | J39: =C39*E39/1000 -> 0 | M39: [Enter source]
A40: 3 | B40: Well-to-Tank — Diesel Fuel (for Scope 1) | C40: 0 | D40: 0 | E40: 16.7 | F40: =C40*D40 -> 0 | G40: =F40*E40 -> 0 | H40: =G40/1000 -> 0 | J40: =C40*E40/1000 -> 0 | M40: [Enter source]
A41: 4 | B41: Well-to-Tank — Gasoline (for Scope 1) | C41: 0 | D41: 0 | E41: 14.8 | F41: =C41*D41 -> 0 | G41: =F41*E41 -> 0 | H41: =G41/1000 -> 0 | J41: =C41*E41/1000 -> 0 | M41: [Enter source]
B42: SUBTOTAL — Category 3 | I42: * it was provided
B43: UK DEFRA/BEIS. EPA does not publish Well‑to‑Tank (WTT) emission factors for electricity or fuels.
B44: c T&D = Transmission & Distribution.
B45: d Upstream emissions from producing, processing, and delivering the fuel before it is used.
A46: CATEGORY 6 — BUSINESS TRAVEL (Activity-Based: Distance × Emission Factor)
...

Sheet Summary & Intensity
B1: CARBON FOOTPRINT SUMMARY & INTENSITY RATIOS
B2: All values pull automatically from Scope 1, 2, and 3 sheets. Review after completing data entry.
A4: SECTION 1 — SCOPE TOTALS (tCO₂e)
A5: Business | B5: Scope | C5: Description | D5: tCO₂e | E5: % of Total (S1+S2+S3) | F5: % of Total (S1+S2 only) | G5: Compared to Prior Year | H5: Target | I5: Notes
A6: WR 2019 | B6: Scope 1 | C6: Direct Emissions (combustion, fleet, fugitive)
A7: WR 2019 | B7: Scope 2 (Market-Based) | C7: Purchased Energy — Market-Based [PRIMARY]
A8: WR 2019 | B8: Scope 2 (Location-Based) | C8: Purchased Energy — Location-Based [SECONDARY]
A9: WR 2019 | B9: Scope 3 | C9: Value Chain Emissions (all categories)
A10: SK 2019 | B10: Scope 1 | C10: Direct Emissions (combustion, fleet, fugitive)
A11: SK 2019 | B11: Scope 2 (Market-Based) | C11: Purchased Energy — Market-Based [PRIMARY]
A12: SK 2019 | B12: Scope 2 (Location-Based) | C12: Purchased Energy — Location-Based [SECONDARY]
A13: SK 2019 | B13: Scope 3 | C13: Value Chain Emissions (all categories)
A14: WR 2020 | B14: Scope 1 | C14: Direct Emissions (combustion, fleet, fugitive)
A15: WR 2020 | B15: Scope 2 (Market-Based) | C15: Purchased Energy — Market-Based [PRIMARY]
A16: WR 2020 | B16: Scope 2 (Location-Based) | C16: Purchased Energy — Location-Based [SECONDARY]
A17: WR 2020 | B17: Scope 3 | C17: Value Chain Emissions (all categories)
... A37: SK 2022 | B37: Scope 3 | C37: Value Chain Emissions (all categories)
A38: WR 2023 | B38: Scope 1 | C38: Direct Emissions (combustion, fleet, fugitive) | D38: =SUM('Scope 1 W'!K22:K24)+'Scope 1 W'!K25 -> 21851880 | E38: =D38/SUM($D$38:$D$41) -> 0.9029992 | F38: =D38/SUM($D$38:$D$40) -> 0.90335954
A39: WR 2023 | B39: Scope 2 (Market-Based) | C39: Purchased Energy — Market-Based [PRIMARY] | D39: ='Scope 2 W'!H62 -> 1267091.2 | E39: =D39/SUM($D$38:$D$41) -> 0.05236082 | F39: =D39/SUM($D$38:$D$40) -> 0.052381715
A40: WR 2023 | B40: Scope 2 (Location-Based) | C40: Purchased Energy — Location-Based [SECONDARY] | D40: ='Scope 2 W'!I62 -> 1070600 | E40: =D40/SUM($D$38:$D$41) -> 0.044241088 | F40: =D40/SUM($D$38:$D$40) -> 0.044258742
A41: WR 2023 | B41: Scope 3 | C41: Value Chain Emissions (all categories) | D41: 9653 | E41: =D41/SUM($D$38:$D$41) -> 0.00039889708
A42: SK 2023 | B42: Scope 1 | C42: Direct Emissions (combustion, fleet, fugitive) | D42: =2415000+4000000 -> 6415000 | E42: =D42/SUM($D$42:$D$45) -> 0.93214182 | F42: =D42/SUM($D$42:$D$44) -> 0.93214182
A43: SK 2023 | B43: Scope 2 (Market-Based) | C43: Purchased Energy — Market-Based [PRIMARY] | D43: 0 | E43: =D43/SUM($D$42:$D$45) -> 0 | F43: =D43/SUM($D$42:$D$44) -> 0
A44: SK 2023 | B44: Scope 2 (Location-Based) | C44: Purchased Energy — Location-Based [SECONDARY] | D44: 467000 | E44: =D44/SUM($D$42:$D$45) -> 0.067858181 | F44: =D44/SUM($D$42:$D$44) -> 0.067858181
A45: SK 2023 | B45: Scope 3 | C45: Value Chain Emissions (all categories) | D45: 0 | E45: =D45/SUM($D$42:$D$45) -> 0
A46: WR 2024 | B46: Scope 1 | C46: Direct Emissions (combustion, fleet, fugitive) | D46: =SUM('Scope 1 W'!K26:K28)+'Scope 1 W'!K29 -> 16445258 | E46: =D46/SUM($D$46:$D$49) -> 0.87641012 | F46: =D46/SUM($D$46:$D$48) -> 0.87685181
A47: WR 2024 | B47: Scope 2 (Market-Based) | C47: Purchased Energy — Market-Based [PRIMARY] | D47: ='Scope 2 W'!H63 -> 1506680.6 | E47: =D47/SUM($D$46:$D$49) -> 0.080294886 | F47: =D47/SUM($D$46:$D$48) -> 0.080335353
A48: WR 2024 | B48: Scope 2 (Location-Based) | C48: Purchased Energy — Location-Based [SECONDARY] | D48: ='Scope 2 W'!I63 -> 802950 | E48: =D48/SUM($D$46:$D$49) -> 0.042791273 | F48: =D48/SUM($D$46:$D$48) -> 0.042812839
